2025-06-12 02:30:19,360 INFO    MainThread:3287 [wandb_setup.py:_flush():70] Current SDK version is 0.19.11
2025-06-12 02:30:19,360 INFO    MainThread:3287 [wandb_setup.py:_flush():70] Configure stats pid to 3287
2025-06-12 02:30:19,360 INFO    MainThread:3287 [wandb_setup.py:_flush():70] Loading settings from /Users/grace/.config/wandb/settings
2025-06-12 02:30:19,360 INFO    MainThread:3287 [wandb_setup.py:_flush():70] Loading settings from /Users/grace/Desktop/00OSU/AI 539 NLP/Final Project/CASTLE_1/CASTLE/wandb/settings
2025-06-12 02:30:19,360 INFO    MainThread:3287 [wandb_setup.py:_flush():70] Loading settings from environment variables
2025-06-12 02:30:19,360 INFO    MainThread:3287 [wandb_init.py:setup_run_log_directory():724] Logging user logs to /Users/grace/Desktop/00OSU/AI 539 NLP/Final Project/CASTLE_1/CASTLE/wandb/run-20250612_023019-puwbwc6i/logs/debug.log
2025-06-12 02:30:19,360 INFO    MainThread:3287 [wandb_init.py:setup_run_log_directory():725] Logging internal logs to /Users/grace/Desktop/00OSU/AI 539 NLP/Final Project/CASTLE_1/CASTLE/wandb/run-20250612_023019-puwbwc6i/logs/debug-internal.log
2025-06-12 02:30:19,360 INFO    MainThread:3287 [wandb_init.py:init():852] calling init triggers
2025-06-12 02:30:19,360 INFO    MainThread:3287 [wandb_init.py:init():857] wandb.init called with sweep_config: {}
config: {'pretrain_epoch': 1000, 'finetune_epoch': 300, 'dec_epoch': 6000, 'dims': [313, 70, 70, 500, 10], 'batch_size': 64, 'corrupt': 0.35, 'n_cluster': 19, 'alpha': 1, 'plot': False, 'pretrain_lr': 0.005, 'pretrain_momentum': 0.9, 'pretrain_step_size': 500, 'pretrain_gamma': 0.5, 'num_workers': 0, 'train_step_size': 100, 'train_gamma': 1, 'train_lr': 0.0001, 'train_momentum': 0.9, 'clusteralg': 'louvain', 'reduce_dim': 'pca', 'dec_lr': 0.005, 'dec_step_size': 2000, 'dec_gamma': 0.2, 'stopping_delta': 1e-07, '_wandb': {}}
2025-06-12 02:30:19,360 INFO    MainThread:3287 [wandb_init.py:init():893] starting backend
2025-06-12 02:30:19,360 INFO    MainThread:3287 [wandb_init.py:init():897] sending inform_init request
2025-06-12 02:30:19,376 INFO    MainThread:3287 [backend.py:_multiprocessing_setup():101] multiprocessing start_methods=spawn,fork,forkserver, using: spawn
2025-06-12 02:30:19,376 INFO    MainThread:3287 [wandb_init.py:init():907] backend started and connected
2025-06-12 02:30:19,380 INFO    MainThread:3287 [wandb_init.py:init():1005] updated telemetry
2025-06-12 02:30:19,406 INFO    MainThread:3287 [wandb_init.py:init():1029] communicating run to backend with 90.0 second timeout
2025-06-12 02:30:19,820 INFO    MainThread:3287 [wandb_init.py:init():1104] starting run threads in backend
2025-06-12 02:30:19,923 INFO    MainThread:3287 [wandb_run.py:_console_start():2573] atexit reg
2025-06-12 02:30:19,924 INFO    MainThread:3287 [wandb_run.py:_redirect():2421] redirect: wrap_raw
2025-06-12 02:30:19,924 INFO    MainThread:3287 [wandb_run.py:_redirect():2490] Wrapping output streams.
2025-06-12 02:30:19,924 INFO    MainThread:3287 [wandb_run.py:_redirect():2513] Redirects installed.
2025-06-12 02:30:19,925 INFO    MainThread:3287 [wandb_init.py:init():1150] run started, returning control to user process
2025-06-12 02:37:16,592 ERROR   MainThread:3287 [redirect.py:_on_write():664] [no run ID] error in stderr callback
Traceback (most recent call last):
  File "/opt/anaconda3/envs/castle/lib/python3.13/site-packages/wandb/sdk/lib/redirect.py", line 662, in _on_write
    cb(written_data)
    ~~^^^^^^^^^^^^^^
  File "/opt/anaconda3/envs/castle/lib/python3.13/site-packages/wandb/sdk/wandb_run.py", line 2500, in <lambda>
    lambda data: self._console_raw_callback("stderr", data),
                 ~~~~~~~~~~~~~~~~~~~~~~~~~~^^^^^^^^^^^^^^^^
  File "/opt/anaconda3/envs/castle/lib/python3.13/site-packages/wandb/sdk/wandb_run.py", line 406, in wrapper
    return func(self, *args, **kwargs)
  File "/opt/anaconda3/envs/castle/lib/python3.13/site-packages/wandb/sdk/wandb_run.py", line 464, in wrapper_fn
    return func(self, *args, **kwargs)
  File "/opt/anaconda3/envs/castle/lib/python3.13/site-packages/wandb/sdk/wandb_run.py", line 1639, in _console_raw_callback
    self._backend.interface.publish_output_raw(name, data)
    ~~~~~~~~~~~~~~~~~~~~~~~~~~~~~~~~~~~~~~~~~~^^^^^^^^^^^^
  File "/opt/anaconda3/envs/castle/lib/python3.13/site-packages/wandb/sdk/interface/interface.py", line 762, in publish_output_raw
    self._publish_output_raw(o)
    ~~~~~~~~~~~~~~~~~~~~~~~~^^^
  File "/opt/anaconda3/envs/castle/lib/python3.13/site-packages/wandb/sdk/interface/interface_shared.py", line 38, in _publish_output_raw
    self._publish(rec)
    ~~~~~~~~~~~~~^^^^^
  File "/opt/anaconda3/envs/castle/lib/python3.13/site-packages/wandb/sdk/interface/interface_sock.py", line 39, in _publish
    self._sock_client.send_record_publish(record)
    ~~~~~~~~~~~~~~~~~~~~~~~~~~~~~~~~~~~~~^^^^^^^^
  File "/opt/anaconda3/envs/castle/lib/python3.13/site-packages/wandb/sdk/lib/sock_client.py", line 174, in send_record_publish
    self.send_server_request(server_req)
    ~~~~~~~~~~~~~~~~~~~~~~~~^^^^^^^^^^^^
  File "/opt/anaconda3/envs/castle/lib/python3.13/site-packages/wandb/sdk/lib/sock_client.py", line 154, in send_server_request
    self._send_message(msg)
    ~~~~~~~~~~~~~~~~~~^^^^^
  File "/opt/anaconda3/envs/castle/lib/python3.13/site-packages/wandb/sdk/lib/sock_client.py", line 151, in _send_message
    self._sendall_with_error_handle(header + data)
    ~~~~~~~~~~~~~~~~~~~~~~~~~~~~~~~^^^^^^^^^^^^^^^
  File "/opt/anaconda3/envs/castle/lib/python3.13/site-packages/wandb/sdk/lib/sock_client.py", line 130, in _sendall_with_error_handle
    sent = self._sock.send(data)
BrokenPipeError: [Errno 32] Broken pipe
2025-06-12 02:37:16,593 WARNING MsgRouterThr:3287 [router.py:message_loop():63] [no run ID] message_loop has been closed
Traceback (most recent call last):
  File "/opt/anaconda3/envs/castle/lib/python3.13/site-packages/wandb/sdk/lib/sock_client.py", line 208, in _read_packet_bytes
    data = self._sock.recv(self._bufsize)
ConnectionResetError: [Errno 54] Connection reset by peer

The above exception was the direct cause of the following exception:

Traceback (most recent call last):
  File "/opt/anaconda3/envs/castle/lib/python3.13/site-packages/wandb/sdk/interface/router_sock.py", line 27, in _read_message
    return self._sock_client.read_server_response(timeout=1)
           ~~~~~~~~~~~~~~~~~~~~~~~~~~~~~~~~~~~~~~^^^^^^^^^^^
  File "/opt/anaconda3/envs/castle/lib/python3.13/site-packages/wandb/sdk/lib/sock_client.py", line 235, in read_server_response
    data = self._read_packet_bytes(timeout=timeout)
  File "/opt/anaconda3/envs/castle/lib/python3.13/site-packages/wandb/sdk/lib/sock_client.py", line 212, in _read_packet_bytes
    raise SockClientClosedError from e
wandb.sdk.lib.sock_client.SockClientClosedError

The above exception was the direct cause of the following exception:

Traceback (most recent call last):
  File "/opt/anaconda3/envs/castle/lib/python3.13/site-packages/wandb/sdk/interface/router.py", line 56, in message_loop
    msg = self._read_message()
  File "/opt/anaconda3/envs/castle/lib/python3.13/site-packages/wandb/sdk/interface/router_sock.py", line 29, in _read_message
    raise MessageRouterClosedError from e
wandb.sdk.interface.router.MessageRouterClosedError
2025-06-12 02:37:16,598 ERROR   MainThread:3287 [redirect.py:_on_write():664] [no run ID] error in stderr callback
Traceback (most recent call last):
  File "/opt/anaconda3/envs/castle/lib/python3.13/site-packages/wandb/sdk/lib/redirect.py", line 662, in _on_write
    cb(written_data)
    ~~^^^^^^^^^^^^^^
  File "/opt/anaconda3/envs/castle/lib/python3.13/site-packages/wandb/sdk/wandb_run.py", line 2500, in <lambda>
    lambda data: self._console_raw_callback("stderr", data),
                 ~~~~~~~~~~~~~~~~~~~~~~~~~~^^^^^^^^^^^^^^^^
  File "/opt/anaconda3/envs/castle/lib/python3.13/site-packages/wandb/sdk/wandb_run.py", line 406, in wrapper
    return func(self, *args, **kwargs)
  File "/opt/anaconda3/envs/castle/lib/python3.13/site-packages/wandb/sdk/wandb_run.py", line 464, in wrapper_fn
    return func(self, *args, **kwargs)
  File "/opt/anaconda3/envs/castle/lib/python3.13/site-packages/wandb/sdk/wandb_run.py", line 1639, in _console_raw_callback
    self._backend.interface.publish_output_raw(name, data)
    ~~~~~~~~~~~~~~~~~~~~~~~~~~~~~~~~~~~~~~~~~~^^^^^^^^^^^^
  File "/opt/anaconda3/envs/castle/lib/python3.13/site-packages/wandb/sdk/interface/interface.py", line 762, in publish_output_raw
    self._publish_output_raw(o)
    ~~~~~~~~~~~~~~~~~~~~~~~~^^^
  File "/opt/anaconda3/envs/castle/lib/python3.13/site-packages/wandb/sdk/interface/interface_shared.py", line 38, in _publish_output_raw
    self._publish(rec)
    ~~~~~~~~~~~~~^^^^^
  File "/opt/anaconda3/envs/castle/lib/python3.13/site-packages/wandb/sdk/interface/interface_sock.py", line 39, in _publish
    self._sock_client.send_record_publish(record)
    ~~~~~~~~~~~~~~~~~~~~~~~~~~~~~~~~~~~~~^^^^^^^^
  File "/opt/anaconda3/envs/castle/lib/python3.13/site-packages/wandb/sdk/lib/sock_client.py", line 174, in send_record_publish
    self.send_server_request(server_req)
    ~~~~~~~~~~~~~~~~~~~~~~~~^^^^^^^^^^^^
  File "/opt/anaconda3/envs/castle/lib/python3.13/site-packages/wandb/sdk/lib/sock_client.py", line 154, in send_server_request
    self._send_message(msg)
    ~~~~~~~~~~~~~~~~~~^^^^^
  File "/opt/anaconda3/envs/castle/lib/python3.13/site-packages/wandb/sdk/lib/sock_client.py", line 151, in _send_message
    self._sendall_with_error_handle(header + data)
    ~~~~~~~~~~~~~~~~~~~~~~~~~~~~~~~^^^^^^^^^^^^^^^
  File "/opt/anaconda3/envs/castle/lib/python3.13/site-packages/wandb/sdk/lib/sock_client.py", line 130, in _sendall_with_error_handle
    sent = self._sock.send(data)
BrokenPipeError: [Errno 32] Broken pipe
2025-06-12 02:37:16,599 INFO    MsgRouterThr:3287 [mailbox.py:close():129] [no run ID] Closing mailbox, abandoning 1 handles.
2025-06-12 02:37:16,599 ERROR   MainThread:3287 [redirect.py:_on_write():664] [no run ID] error in stderr callback
Traceback (most recent call last):
  File "/opt/anaconda3/envs/castle/lib/python3.13/site-packages/wandb/sdk/lib/redirect.py", line 662, in _on_write
    cb(written_data)
    ~~^^^^^^^^^^^^^^
  File "/opt/anaconda3/envs/castle/lib/python3.13/site-packages/wandb/sdk/wandb_run.py", line 2500, in <lambda>
    lambda data: self._console_raw_callback("stderr", data),
                 ~~~~~~~~~~~~~~~~~~~~~~~~~~^^^^^^^^^^^^^^^^
  File "/opt/anaconda3/envs/castle/lib/python3.13/site-packages/wandb/sdk/wandb_run.py", line 406, in wrapper
    return func(self, *args, **kwargs)
  File "/opt/anaconda3/envs/castle/lib/python3.13/site-packages/wandb/sdk/wandb_run.py", line 464, in wrapper_fn
    return func(self, *args, **kwargs)
  File "/opt/anaconda3/envs/castle/lib/python3.13/site-packages/wandb/sdk/wandb_run.py", line 1639, in _console_raw_callback
    self._backend.interface.publish_output_raw(name, data)
    ~~~~~~~~~~~~~~~~~~~~~~~~~~~~~~~~~~~~~~~~~~^^^^^^^^^^^^
  File "/opt/anaconda3/envs/castle/lib/python3.13/site-packages/wandb/sdk/interface/interface.py", line 762, in publish_output_raw
    self._publish_output_raw(o)
    ~~~~~~~~~~~~~~~~~~~~~~~~^^^
  File "/opt/anaconda3/envs/castle/lib/python3.13/site-packages/wandb/sdk/interface/interface_shared.py", line 38, in _publish_output_raw
    self._publish(rec)
    ~~~~~~~~~~~~~^^^^^
  File "/opt/anaconda3/envs/castle/lib/python3.13/site-packages/wandb/sdk/interface/interface_sock.py", line 39, in _publish
    self._sock_client.send_record_publish(record)
    ~~~~~~~~~~~~~~~~~~~~~~~~~~~~~~~~~~~~~^^^^^^^^
  File "/opt/anaconda3/envs/castle/lib/python3.13/site-packages/wandb/sdk/lib/sock_client.py", line 174, in send_record_publish
    self.send_server_request(server_req)
    ~~~~~~~~~~~~~~~~~~~~~~~~^^^^^^^^^^^^
  File "/opt/anaconda3/envs/castle/lib/python3.13/site-packages/wandb/sdk/lib/sock_client.py", line 154, in send_server_request
    self._send_message(msg)
    ~~~~~~~~~~~~~~~~~~^^^^^
  File "/opt/anaconda3/envs/castle/lib/python3.13/site-packages/wandb/sdk/lib/sock_client.py", line 151, in _send_message
    self._sendall_with_error_handle(header + data)
    ~~~~~~~~~~~~~~~~~~~~~~~~~~~~~~~^^^^^^^^^^^^^^^
  File "/opt/anaconda3/envs/castle/lib/python3.13/site-packages/wandb/sdk/lib/sock_client.py", line 130, in _sendall_with_error_handle
    sent = self._sock.send(data)
BrokenPipeError: [Errno 32] Broken pipe
2025-06-12 02:37:16,600 ERROR   MainThread:3287 [redirect.py:_on_write():664] [no run ID] error in stderr callback
Traceback (most recent call last):
  File "/opt/anaconda3/envs/castle/lib/python3.13/site-packages/wandb/sdk/lib/redirect.py", line 662, in _on_write
    cb(written_data)
    ~~^^^^^^^^^^^^^^
  File "/opt/anaconda3/envs/castle/lib/python3.13/site-packages/wandb/sdk/wandb_run.py", line 2500, in <lambda>
    lambda data: self._console_raw_callback("stderr", data),
                 ~~~~~~~~~~~~~~~~~~~~~~~~~~^^^^^^^^^^^^^^^^
  File "/opt/anaconda3/envs/castle/lib/python3.13/site-packages/wandb/sdk/wandb_run.py", line 406, in wrapper
    return func(self, *args, **kwargs)
  File "/opt/anaconda3/envs/castle/lib/python3.13/site-packages/wandb/sdk/wandb_run.py", line 464, in wrapper_fn
    return func(self, *args, **kwargs)
  File "/opt/anaconda3/envs/castle/lib/python3.13/site-packages/wandb/sdk/wandb_run.py", line 1639, in _console_raw_callback
    self._backend.interface.publish_output_raw(name, data)
    ~~~~~~~~~~~~~~~~~~~~~~~~~~~~~~~~~~~~~~~~~~^^^^^^^^^^^^
  File "/opt/anaconda3/envs/castle/lib/python3.13/site-packages/wandb/sdk/interface/interface.py", line 762, in publish_output_raw
    self._publish_output_raw(o)
    ~~~~~~~~~~~~~~~~~~~~~~~~^^^
  File "/opt/anaconda3/envs/castle/lib/python3.13/site-packages/wandb/sdk/interface/interface_shared.py", line 38, in _publish_output_raw
    self._publish(rec)
    ~~~~~~~~~~~~~^^^^^
  File "/opt/anaconda3/envs/castle/lib/python3.13/site-packages/wandb/sdk/interface/interface_sock.py", line 39, in _publish
    self._sock_client.send_record_publish(record)
    ~~~~~~~~~~~~~~~~~~~~~~~~~~~~~~~~~~~~~^^^^^^^^
  File "/opt/anaconda3/envs/castle/lib/python3.13/site-packages/wandb/sdk/lib/sock_client.py", line 174, in send_record_publish
    self.send_server_request(server_req)
    ~~~~~~~~~~~~~~~~~~~~~~~~^^^^^^^^^^^^
  File "/opt/anaconda3/envs/castle/lib/python3.13/site-packages/wandb/sdk/lib/sock_client.py", line 154, in send_server_request
    self._send_message(msg)
    ~~~~~~~~~~~~~~~~~~^^^^^
  File "/opt/anaconda3/envs/castle/lib/python3.13/site-packages/wandb/sdk/lib/sock_client.py", line 151, in _send_message
    self._sendall_with_error_handle(header + data)
    ~~~~~~~~~~~~~~~~~~~~~~~~~~~~~~~^^^^^^^^^^^^^^^
  File "/opt/anaconda3/envs/castle/lib/python3.13/site-packages/wandb/sdk/lib/sock_client.py", line 130, in _sendall_with_error_handle
    sent = self._sock.send(data)
BrokenPipeError: [Errno 32] Broken pipe
2025-06-12 02:37:16,602 ERROR   MainThread:3287 [redirect.py:_on_write():664] [no run ID] error in stderr callback
Traceback (most recent call last):
  File "/opt/anaconda3/envs/castle/lib/python3.13/site-packages/wandb/sdk/lib/redirect.py", line 662, in _on_write
    cb(written_data)
    ~~^^^^^^^^^^^^^^
  File "/opt/anaconda3/envs/castle/lib/python3.13/site-packages/wandb/sdk/wandb_run.py", line 2500, in <lambda>
    lambda data: self._console_raw_callback("stderr", data),
                 ~~~~~~~~~~~~~~~~~~~~~~~~~~^^^^^^^^^^^^^^^^
  File "/opt/anaconda3/envs/castle/lib/python3.13/site-packages/wandb/sdk/wandb_run.py", line 406, in wrapper
    return func(self, *args, **kwargs)
  File "/opt/anaconda3/envs/castle/lib/python3.13/site-packages/wandb/sdk/wandb_run.py", line 464, in wrapper_fn
    return func(self, *args, **kwargs)
  File "/opt/anaconda3/envs/castle/lib/python3.13/site-packages/wandb/sdk/wandb_run.py", line 1639, in _console_raw_callback
    self._backend.interface.publish_output_raw(name, data)
    ~~~~~~~~~~~~~~~~~~~~~~~~~~~~~~~~~~~~~~~~~~^^^^^^^^^^^^
  File "/opt/anaconda3/envs/castle/lib/python3.13/site-packages/wandb/sdk/interface/interface.py", line 762, in publish_output_raw
    self._publish_output_raw(o)
    ~~~~~~~~~~~~~~~~~~~~~~~~^^^
  File "/opt/anaconda3/envs/castle/lib/python3.13/site-packages/wandb/sdk/interface/interface_shared.py", line 38, in _publish_output_raw
    self._publish(rec)
    ~~~~~~~~~~~~~^^^^^
  File "/opt/anaconda3/envs/castle/lib/python3.13/site-packages/wandb/sdk/interface/interface_sock.py", line 39, in _publish
    self._sock_client.send_record_publish(record)
    ~~~~~~~~~~~~~~~~~~~~~~~~~~~~~~~~~~~~~^^^^^^^^
  File "/opt/anaconda3/envs/castle/lib/python3.13/site-packages/wandb/sdk/lib/sock_client.py", line 174, in send_record_publish
    self.send_server_request(server_req)
    ~~~~~~~~~~~~~~~~~~~~~~~~^^^^^^^^^^^^
  File "/opt/anaconda3/envs/castle/lib/python3.13/site-packages/wandb/sdk/lib/sock_client.py", line 154, in send_server_request
    self._send_message(msg)
    ~~~~~~~~~~~~~~~~~~^^^^^
  File "/opt/anaconda3/envs/castle/lib/python3.13/site-packages/wandb/sdk/lib/sock_client.py", line 151, in _send_message
    self._sendall_with_error_handle(header + data)
    ~~~~~~~~~~~~~~~~~~~~~~~~~~~~~~~^^^^^^^^^^^^^^^
  File "/opt/anaconda3/envs/castle/lib/python3.13/site-packages/wandb/sdk/lib/sock_client.py", line 130, in _sendall_with_error_handle
    sent = self._sock.send(data)
BrokenPipeError: [Errno 32] Broken pipe
2025-06-12 02:37:16,603 ERROR   MainThread:3287 [redirect.py:_on_write():664] [no run ID] error in stderr callback
Traceback (most recent call last):
  File "/opt/anaconda3/envs/castle/lib/python3.13/site-packages/wandb/sdk/lib/redirect.py", line 662, in _on_write
    cb(written_data)
    ~~^^^^^^^^^^^^^^
  File "/opt/anaconda3/envs/castle/lib/python3.13/site-packages/wandb/sdk/wandb_run.py", line 2500, in <lambda>
    lambda data: self._console_raw_callback("stderr", data),
                 ~~~~~~~~~~~~~~~~~~~~~~~~~~^^^^^^^^^^^^^^^^
  File "/opt/anaconda3/envs/castle/lib/python3.13/site-packages/wandb/sdk/wandb_run.py", line 406, in wrapper
    return func(self, *args, **kwargs)
  File "/opt/anaconda3/envs/castle/lib/python3.13/site-packages/wandb/sdk/wandb_run.py", line 464, in wrapper_fn
    return func(self, *args, **kwargs)
  File "/opt/anaconda3/envs/castle/lib/python3.13/site-packages/wandb/sdk/wandb_run.py", line 1639, in _console_raw_callback
    self._backend.interface.publish_output_raw(name, data)
    ~~~~~~~~~~~~~~~~~~~~~~~~~~~~~~~~~~~~~~~~~~^^^^^^^^^^^^
  File "/opt/anaconda3/envs/castle/lib/python3.13/site-packages/wandb/sdk/interface/interface.py", line 762, in publish_output_raw
    self._publish_output_raw(o)
    ~~~~~~~~~~~~~~~~~~~~~~~~^^^
  File "/opt/anaconda3/envs/castle/lib/python3.13/site-packages/wandb/sdk/interface/interface_shared.py", line 38, in _publish_output_raw
    self._publish(rec)
    ~~~~~~~~~~~~~^^^^^
  File "/opt/anaconda3/envs/castle/lib/python3.13/site-packages/wandb/sdk/interface/interface_sock.py", line 39, in _publish
    self._sock_client.send_record_publish(record)
    ~~~~~~~~~~~~~~~~~~~~~~~~~~~~~~~~~~~~~^^^^^^^^
  File "/opt/anaconda3/envs/castle/lib/python3.13/site-packages/wandb/sdk/lib/sock_client.py", line 174, in send_record_publish
    self.send_server_request(server_req)
    ~~~~~~~~~~~~~~~~~~~~~~~~^^^^^^^^^^^^
  File "/opt/anaconda3/envs/castle/lib/python3.13/site-packages/wandb/sdk/lib/sock_client.py", line 154, in send_server_request
    self._send_message(msg)
    ~~~~~~~~~~~~~~~~~~^^^^^
  File "/opt/anaconda3/envs/castle/lib/python3.13/site-packages/wandb/sdk/lib/sock_client.py", line 151, in _send_message
    self._sendall_with_error_handle(header + data)
    ~~~~~~~~~~~~~~~~~~~~~~~~~~~~~~~^^^^^^^^^^^^^^^
  File "/opt/anaconda3/envs/castle/lib/python3.13/site-packages/wandb/sdk/lib/sock_client.py", line 130, in _sendall_with_error_handle
    sent = self._sock.send(data)
BrokenPipeError: [Errno 32] Broken pipe
2025-06-12 02:37:16,604 ERROR   MainThread:3287 [redirect.py:_on_write():664] [no run ID] error in stderr callback
Traceback (most recent call last):
  File "/opt/anaconda3/envs/castle/lib/python3.13/site-packages/wandb/sdk/lib/redirect.py", line 662, in _on_write
    cb(written_data)
    ~~^^^^^^^^^^^^^^
  File "/opt/anaconda3/envs/castle/lib/python3.13/site-packages/wandb/sdk/wandb_run.py", line 2500, in <lambda>
    lambda data: self._console_raw_callback("stderr", data),
                 ~~~~~~~~~~~~~~~~~~~~~~~~~~^^^^^^^^^^^^^^^^
  File "/opt/anaconda3/envs/castle/lib/python3.13/site-packages/wandb/sdk/wandb_run.py", line 406, in wrapper
    return func(self, *args, **kwargs)
  File "/opt/anaconda3/envs/castle/lib/python3.13/site-packages/wandb/sdk/wandb_run.py", line 464, in wrapper_fn
    return func(self, *args, **kwargs)
  File "/opt/anaconda3/envs/castle/lib/python3.13/site-packages/wandb/sdk/wandb_run.py", line 1639, in _console_raw_callback
    self._backend.interface.publish_output_raw(name, data)
    ~~~~~~~~~~~~~~~~~~~~~~~~~~~~~~~~~~~~~~~~~~^^^^^^^^^^^^
  File "/opt/anaconda3/envs/castle/lib/python3.13/site-packages/wandb/sdk/interface/interface.py", line 762, in publish_output_raw
    self._publish_output_raw(o)
    ~~~~~~~~~~~~~~~~~~~~~~~~^^^
  File "/opt/anaconda3/envs/castle/lib/python3.13/site-packages/wandb/sdk/interface/interface_shared.py", line 38, in _publish_output_raw
    self._publish(rec)
    ~~~~~~~~~~~~~^^^^^
  File "/opt/anaconda3/envs/castle/lib/python3.13/site-packages/wandb/sdk/interface/interface_sock.py", line 39, in _publish
    self._sock_client.send_record_publish(record)
    ~~~~~~~~~~~~~~~~~~~~~~~~~~~~~~~~~~~~~^^^^^^^^
  File "/opt/anaconda3/envs/castle/lib/python3.13/site-packages/wandb/sdk/lib/sock_client.py", line 174, in send_record_publish
    self.send_server_request(server_req)
    ~~~~~~~~~~~~~~~~~~~~~~~~^^^^^^^^^^^^
  File "/opt/anaconda3/envs/castle/lib/python3.13/site-packages/wandb/sdk/lib/sock_client.py", line 154, in send_server_request
    self._send_message(msg)
    ~~~~~~~~~~~~~~~~~~^^^^^
  File "/opt/anaconda3/envs/castle/lib/python3.13/site-packages/wandb/sdk/lib/sock_client.py", line 151, in _send_message
    self._sendall_with_error_handle(header + data)
    ~~~~~~~~~~~~~~~~~~~~~~~~~~~~~~~^^^^^^^^^^^^^^^
  File "/opt/anaconda3/envs/castle/lib/python3.13/site-packages/wandb/sdk/lib/sock_client.py", line 130, in _sendall_with_error_handle
    sent = self._sock.send(data)
BrokenPipeError: [Errno 32] Broken pipe
2025-06-12 02:37:16,605 ERROR   MainThread:3287 [redirect.py:_on_write():664] [no run ID] error in stderr callback
Traceback (most recent call last):
  File "/opt/anaconda3/envs/castle/lib/python3.13/site-packages/wandb/sdk/lib/redirect.py", line 662, in _on_write
    cb(written_data)
    ~~^^^^^^^^^^^^^^
  File "/opt/anaconda3/envs/castle/lib/python3.13/site-packages/wandb/sdk/wandb_run.py", line 2500, in <lambda>
    lambda data: self._console_raw_callback("stderr", data),
                 ~~~~~~~~~~~~~~~~~~~~~~~~~~^^^^^^^^^^^^^^^^
  File "/opt/anaconda3/envs/castle/lib/python3.13/site-packages/wandb/sdk/wandb_run.py", line 406, in wrapper
    return func(self, *args, **kwargs)
  File "/opt/anaconda3/envs/castle/lib/python3.13/site-packages/wandb/sdk/wandb_run.py", line 464, in wrapper_fn
    return func(self, *args, **kwargs)
  File "/opt/anaconda3/envs/castle/lib/python3.13/site-packages/wandb/sdk/wandb_run.py", line 1639, in _console_raw_callback
    self._backend.interface.publish_output_raw(name, data)
    ~~~~~~~~~~~~~~~~~~~~~~~~~~~~~~~~~~~~~~~~~~^^^^^^^^^^^^
  File "/opt/anaconda3/envs/castle/lib/python3.13/site-packages/wandb/sdk/interface/interface.py", line 762, in publish_output_raw
    self._publish_output_raw(o)
    ~~~~~~~~~~~~~~~~~~~~~~~~^^^
  File "/opt/anaconda3/envs/castle/lib/python3.13/site-packages/wandb/sdk/interface/interface_shared.py", line 38, in _publish_output_raw
    self._publish(rec)
    ~~~~~~~~~~~~~^^^^^
  File "/opt/anaconda3/envs/castle/lib/python3.13/site-packages/wandb/sdk/interface/interface_sock.py", line 39, in _publish
    self._sock_client.send_record_publish(record)
    ~~~~~~~~~~~~~~~~~~~~~~~~~~~~~~~~~~~~~^^^^^^^^
  File "/opt/anaconda3/envs/castle/lib/python3.13/site-packages/wandb/sdk/lib/sock_client.py", line 174, in send_record_publish
    self.send_server_request(server_req)
    ~~~~~~~~~~~~~~~~~~~~~~~~^^^^^^^^^^^^
  File "/opt/anaconda3/envs/castle/lib/python3.13/site-packages/wandb/sdk/lib/sock_client.py", line 154, in send_server_request
    self._send_message(msg)
    ~~~~~~~~~~~~~~~~~~^^^^^
  File "/opt/anaconda3/envs/castle/lib/python3.13/site-packages/wandb/sdk/lib/sock_client.py", line 151, in _send_message
    self._sendall_with_error_handle(header + data)
    ~~~~~~~~~~~~~~~~~~~~~~~~~~~~~~~^^^^^^^^^^^^^^^
  File "/opt/anaconda3/envs/castle/lib/python3.13/site-packages/wandb/sdk/lib/sock_client.py", line 130, in _sendall_with_error_handle
    sent = self._sock.send(data)
BrokenPipeError: [Errno 32] Broken pipe
2025-06-12 02:37:16,606 ERROR   MainThread:3287 [redirect.py:_on_write():664] [no run ID] error in stderr callback
Traceback (most recent call last):
  File "/opt/anaconda3/envs/castle/lib/python3.13/site-packages/wandb/sdk/lib/redirect.py", line 662, in _on_write
    cb(written_data)
    ~~^^^^^^^^^^^^^^
  File "/opt/anaconda3/envs/castle/lib/python3.13/site-packages/wandb/sdk/wandb_run.py", line 2500, in <lambda>
    lambda data: self._console_raw_callback("stderr", data),
                 ~~~~~~~~~~~~~~~~~~~~~~~~~~^^^^^^^^^^^^^^^^
  File "/opt/anaconda3/envs/castle/lib/python3.13/site-packages/wandb/sdk/wandb_run.py", line 406, in wrapper
    return func(self, *args, **kwargs)
  File "/opt/anaconda3/envs/castle/lib/python3.13/site-packages/wandb/sdk/wandb_run.py", line 464, in wrapper_fn
    return func(self, *args, **kwargs)
  File "/opt/anaconda3/envs/castle/lib/python3.13/site-packages/wandb/sdk/wandb_run.py", line 1639, in _console_raw_callback
    self._backend.interface.publish_output_raw(name, data)
    ~~~~~~~~~~~~~~~~~~~~~~~~~~~~~~~~~~~~~~~~~~^^^^^^^^^^^^
  File "/opt/anaconda3/envs/castle/lib/python3.13/site-packages/wandb/sdk/interface/interface.py", line 762, in publish_output_raw
    self._publish_output_raw(o)
    ~~~~~~~~~~~~~~~~~~~~~~~~^^^
  File "/opt/anaconda3/envs/castle/lib/python3.13/site-packages/wandb/sdk/interface/interface_shared.py", line 38, in _publish_output_raw
    self._publish(rec)
    ~~~~~~~~~~~~~^^^^^
  File "/opt/anaconda3/envs/castle/lib/python3.13/site-packages/wandb/sdk/interface/interface_sock.py", line 39, in _publish
    self._sock_client.send_record_publish(record)
    ~~~~~~~~~~~~~~~~~~~~~~~~~~~~~~~~~~~~~^^^^^^^^
  File "/opt/anaconda3/envs/castle/lib/python3.13/site-packages/wandb/sdk/lib/sock_client.py", line 174, in send_record_publish
    self.send_server_request(server_req)
    ~~~~~~~~~~~~~~~~~~~~~~~~^^^^^^^^^^^^
  File "/opt/anaconda3/envs/castle/lib/python3.13/site-packages/wandb/sdk/lib/sock_client.py", line 154, in send_server_request
    self._send_message(msg)
    ~~~~~~~~~~~~~~~~~~^^^^^
  File "/opt/anaconda3/envs/castle/lib/python3.13/site-packages/wandb/sdk/lib/sock_client.py", line 151, in _send_message
    self._sendall_with_error_handle(header + data)
    ~~~~~~~~~~~~~~~~~~~~~~~~~~~~~~~^^^^^^^^^^^^^^^
  File "/opt/anaconda3/envs/castle/lib/python3.13/site-packages/wandb/sdk/lib/sock_client.py", line 130, in _sendall_with_error_handle
    sent = self._sock.send(data)
BrokenPipeError: [Errno 32] Broken pipe
2025-06-12 02:37:16,607 ERROR   MainThread:3287 [redirect.py:_on_write():664] [no run ID] error in stderr callback
Traceback (most recent call last):
  File "/opt/anaconda3/envs/castle/lib/python3.13/site-packages/wandb/sdk/lib/redirect.py", line 662, in _on_write
    cb(written_data)
    ~~^^^^^^^^^^^^^^
  File "/opt/anaconda3/envs/castle/lib/python3.13/site-packages/wandb/sdk/wandb_run.py", line 2500, in <lambda>
    lambda data: self._console_raw_callback("stderr", data),
                 ~~~~~~~~~~~~~~~~~~~~~~~~~~^^^^^^^^^^^^^^^^
  File "/opt/anaconda3/envs/castle/lib/python3.13/site-packages/wandb/sdk/wandb_run.py", line 406, in wrapper
    return func(self, *args, **kwargs)
  File "/opt/anaconda3/envs/castle/lib/python3.13/site-packages/wandb/sdk/wandb_run.py", line 464, in wrapper_fn
    return func(self, *args, **kwargs)
  File "/opt/anaconda3/envs/castle/lib/python3.13/site-packages/wandb/sdk/wandb_run.py", line 1639, in _console_raw_callback
    self._backend.interface.publish_output_raw(name, data)
    ~~~~~~~~~~~~~~~~~~~~~~~~~~~~~~~~~~~~~~~~~~^^^^^^^^^^^^
  File "/opt/anaconda3/envs/castle/lib/python3.13/site-packages/wandb/sdk/interface/interface.py", line 762, in publish_output_raw
    self._publish_output_raw(o)
    ~~~~~~~~~~~~~~~~~~~~~~~~^^^
  File "/opt/anaconda3/envs/castle/lib/python3.13/site-packages/wandb/sdk/interface/interface_shared.py", line 38, in _publish_output_raw
    self._publish(rec)
    ~~~~~~~~~~~~~^^^^^
  File "/opt/anaconda3/envs/castle/lib/python3.13/site-packages/wandb/sdk/interface/interface_sock.py", line 39, in _publish
    self._sock_client.send_record_publish(record)
    ~~~~~~~~~~~~~~~~~~~~~~~~~~~~~~~~~~~~~^^^^^^^^
  File "/opt/anaconda3/envs/castle/lib/python3.13/site-packages/wandb/sdk/lib/sock_client.py", line 174, in send_record_publish
    self.send_server_request(server_req)
    ~~~~~~~~~~~~~~~~~~~~~~~~^^^^^^^^^^^^
  File "/opt/anaconda3/envs/castle/lib/python3.13/site-packages/wandb/sdk/lib/sock_client.py", line 154, in send_server_request
    self._send_message(msg)
    ~~~~~~~~~~~~~~~~~~^^^^^
  File "/opt/anaconda3/envs/castle/lib/python3.13/site-packages/wandb/sdk/lib/sock_client.py", line 151, in _send_message
    self._sendall_with_error_handle(header + data)
    ~~~~~~~~~~~~~~~~~~~~~~~~~~~~~~~^^^^^^^^^^^^^^^
  File "/opt/anaconda3/envs/castle/lib/python3.13/site-packages/wandb/sdk/lib/sock_client.py", line 130, in _sendall_with_error_handle
    sent = self._sock.send(data)
BrokenPipeError: [Errno 32] Broken pipe
2025-06-12 02:37:16,607 ERROR   MainThread:3287 [redirect.py:_on_write():664] [no run ID] error in stderr callback
Traceback (most recent call last):
  File "/opt/anaconda3/envs/castle/lib/python3.13/site-packages/wandb/sdk/lib/redirect.py", line 662, in _on_write
    cb(written_data)
    ~~^^^^^^^^^^^^^^
  File "/opt/anaconda3/envs/castle/lib/python3.13/site-packages/wandb/sdk/wandb_run.py", line 2500, in <lambda>
    lambda data: self._console_raw_callback("stderr", data),
                 ~~~~~~~~~~~~~~~~~~~~~~~~~~^^^^^^^^^^^^^^^^
  File "/opt/anaconda3/envs/castle/lib/python3.13/site-packages/wandb/sdk/wandb_run.py", line 406, in wrapper
    return func(self, *args, **kwargs)
  File "/opt/anaconda3/envs/castle/lib/python3.13/site-packages/wandb/sdk/wandb_run.py", line 464, in wrapper_fn
    return func(self, *args, **kwargs)
  File "/opt/anaconda3/envs/castle/lib/python3.13/site-packages/wandb/sdk/wandb_run.py", line 1639, in _console_raw_callback
    self._backend.interface.publish_output_raw(name, data)
    ~~~~~~~~~~~~~~~~~~~~~~~~~~~~~~~~~~~~~~~~~~^^^^^^^^^^^^
  File "/opt/anaconda3/envs/castle/lib/python3.13/site-packages/wandb/sdk/interface/interface.py", line 762, in publish_output_raw
    self._publish_output_raw(o)
    ~~~~~~~~~~~~~~~~~~~~~~~~^^^
  File "/opt/anaconda3/envs/castle/lib/python3.13/site-packages/wandb/sdk/interface/interface_shared.py", line 38, in _publish_output_raw
    self._publish(rec)
    ~~~~~~~~~~~~~^^^^^
  File "/opt/anaconda3/envs/castle/lib/python3.13/site-packages/wandb/sdk/interface/interface_sock.py", line 39, in _publish
    self._sock_client.send_record_publish(record)
    ~~~~~~~~~~~~~~~~~~~~~~~~~~~~~~~~~~~~~^^^^^^^^
  File "/opt/anaconda3/envs/castle/lib/python3.13/site-packages/wandb/sdk/lib/sock_client.py", line 174, in send_record_publish
    self.send_server_request(server_req)
    ~~~~~~~~~~~~~~~~~~~~~~~~^^^^^^^^^^^^
  File "/opt/anaconda3/envs/castle/lib/python3.13/site-packages/wandb/sdk/lib/sock_client.py", line 154, in send_server_request
    self._send_message(msg)
    ~~~~~~~~~~~~~~~~~~^^^^^
  File "/opt/anaconda3/envs/castle/lib/python3.13/site-packages/wandb/sdk/lib/sock_client.py", line 151, in _send_message
    self._sendall_with_error_handle(header + data)
    ~~~~~~~~~~~~~~~~~~~~~~~~~~~~~~~^^^^^^^^^^^^^^^
  File "/opt/anaconda3/envs/castle/lib/python3.13/site-packages/wandb/sdk/lib/sock_client.py", line 130, in _sendall_with_error_handle
    sent = self._sock.send(data)
BrokenPipeError: [Errno 32] Broken pipe
2025-06-12 02:37:16,608 ERROR   MainThread:3287 [redirect.py:_on_write():664] [no run ID] error in stderr callback
Traceback (most recent call last):
  File "/opt/anaconda3/envs/castle/lib/python3.13/site-packages/wandb/sdk/lib/redirect.py", line 662, in _on_write
    cb(written_data)
    ~~^^^^^^^^^^^^^^
  File "/opt/anaconda3/envs/castle/lib/python3.13/site-packages/wandb/sdk/wandb_run.py", line 2500, in <lambda>
    lambda data: self._console_raw_callback("stderr", data),
                 ~~~~~~~~~~~~~~~~~~~~~~~~~~^^^^^^^^^^^^^^^^
  File "/opt/anaconda3/envs/castle/lib/python3.13/site-packages/wandb/sdk/wandb_run.py", line 406, in wrapper
    return func(self, *args, **kwargs)
  File "/opt/anaconda3/envs/castle/lib/python3.13/site-packages/wandb/sdk/wandb_run.py", line 464, in wrapper_fn
    return func(self, *args, **kwargs)
  File "/opt/anaconda3/envs/castle/lib/python3.13/site-packages/wandb/sdk/wandb_run.py", line 1639, in _console_raw_callback
    self._backend.interface.publish_output_raw(name, data)
    ~~~~~~~~~~~~~~~~~~~~~~~~~~~~~~~~~~~~~~~~~~^^^^^^^^^^^^
  File "/opt/anaconda3/envs/castle/lib/python3.13/site-packages/wandb/sdk/interface/interface.py", line 762, in publish_output_raw
    self._publish_output_raw(o)
    ~~~~~~~~~~~~~~~~~~~~~~~~^^^
  File "/opt/anaconda3/envs/castle/lib/python3.13/site-packages/wandb/sdk/interface/interface_shared.py", line 38, in _publish_output_raw
    self._publish(rec)
    ~~~~~~~~~~~~~^^^^^
  File "/opt/anaconda3/envs/castle/lib/python3.13/site-packages/wandb/sdk/interface/interface_sock.py", line 39, in _publish
    self._sock_client.send_record_publish(record)
    ~~~~~~~~~~~~~~~~~~~~~~~~~~~~~~~~~~~~~^^^^^^^^
  File "/opt/anaconda3/envs/castle/lib/python3.13/site-packages/wandb/sdk/lib/sock_client.py", line 174, in send_record_publish
    self.send_server_request(server_req)
    ~~~~~~~~~~~~~~~~~~~~~~~~^^^^^^^^^^^^
  File "/opt/anaconda3/envs/castle/lib/python3.13/site-packages/wandb/sdk/lib/sock_client.py", line 154, in send_server_request
    self._send_message(msg)
    ~~~~~~~~~~~~~~~~~~^^^^^
  File "/opt/anaconda3/envs/castle/lib/python3.13/site-packages/wandb/sdk/lib/sock_client.py", line 151, in _send_message
    self._sendall_with_error_handle(header + data)
    ~~~~~~~~~~~~~~~~~~~~~~~~~~~~~~~^^^^^^^^^^^^^^^
  File "/opt/anaconda3/envs/castle/lib/python3.13/site-packages/wandb/sdk/lib/sock_client.py", line 130, in _sendall_with_error_handle
    sent = self._sock.send(data)
BrokenPipeError: [Errno 32] Broken pipe
2025-06-12 02:37:16,608 ERROR   MainThread:3287 [redirect.py:_on_write():664] [no run ID] error in stderr callback
Traceback (most recent call last):
  File "/opt/anaconda3/envs/castle/lib/python3.13/site-packages/wandb/sdk/lib/redirect.py", line 662, in _on_write
    cb(written_data)
    ~~^^^^^^^^^^^^^^
  File "/opt/anaconda3/envs/castle/lib/python3.13/site-packages/wandb/sdk/wandb_run.py", line 2500, in <lambda>
    lambda data: self._console_raw_callback("stderr", data),
                 ~~~~~~~~~~~~~~~~~~~~~~~~~~^^^^^^^^^^^^^^^^
  File "/opt/anaconda3/envs/castle/lib/python3.13/site-packages/wandb/sdk/wandb_run.py", line 406, in wrapper
    return func(self, *args, **kwargs)
  File "/opt/anaconda3/envs/castle/lib/python3.13/site-packages/wandb/sdk/wandb_run.py", line 464, in wrapper_fn
    return func(self, *args, **kwargs)
  File "/opt/anaconda3/envs/castle/lib/python3.13/site-packages/wandb/sdk/wandb_run.py", line 1639, in _console_raw_callback
    self._backend.interface.publish_output_raw(name, data)
    ~~~~~~~~~~~~~~~~~~~~~~~~~~~~~~~~~~~~~~~~~~^^^^^^^^^^^^
  File "/opt/anaconda3/envs/castle/lib/python3.13/site-packages/wandb/sdk/interface/interface.py", line 762, in publish_output_raw
    self._publish_output_raw(o)
    ~~~~~~~~~~~~~~~~~~~~~~~~^^^
  File "/opt/anaconda3/envs/castle/lib/python3.13/site-packages/wandb/sdk/interface/interface_shared.py", line 38, in _publish_output_raw
    self._publish(rec)
    ~~~~~~~~~~~~~^^^^^
  File "/opt/anaconda3/envs/castle/lib/python3.13/site-packages/wandb/sdk/interface/interface_sock.py", line 39, in _publish
    self._sock_client.send_record_publish(record)
    ~~~~~~~~~~~~~~~~~~~~~~~~~~~~~~~~~~~~~^^^^^^^^
  File "/opt/anaconda3/envs/castle/lib/python3.13/site-packages/wandb/sdk/lib/sock_client.py", line 174, in send_record_publish
    self.send_server_request(server_req)
    ~~~~~~~~~~~~~~~~~~~~~~~~^^^^^^^^^^^^
  File "/opt/anaconda3/envs/castle/lib/python3.13/site-packages/wandb/sdk/lib/sock_client.py", line 154, in send_server_request
    self._send_message(msg)
    ~~~~~~~~~~~~~~~~~~^^^^^
  File "/opt/anaconda3/envs/castle/lib/python3.13/site-packages/wandb/sdk/lib/sock_client.py", line 151, in _send_message
    self._sendall_with_error_handle(header + data)
    ~~~~~~~~~~~~~~~~~~~~~~~~~~~~~~~^^^^^^^^^^^^^^^
  File "/opt/anaconda3/envs/castle/lib/python3.13/site-packages/wandb/sdk/lib/sock_client.py", line 130, in _sendall_with_error_handle
    sent = self._sock.send(data)
BrokenPipeError: [Errno 32] Broken pipe
2025-06-12 02:37:16,609 ERROR   MainThread:3287 [redirect.py:_on_write():664] [no run ID] error in stderr callback
Traceback (most recent call last):
  File "/opt/anaconda3/envs/castle/lib/python3.13/site-packages/wandb/sdk/lib/redirect.py", line 662, in _on_write
    cb(written_data)
    ~~^^^^^^^^^^^^^^
  File "/opt/anaconda3/envs/castle/lib/python3.13/site-packages/wandb/sdk/wandb_run.py", line 2500, in <lambda>
    lambda data: self._console_raw_callback("stderr", data),
                 ~~~~~~~~~~~~~~~~~~~~~~~~~~^^^^^^^^^^^^^^^^
  File "/opt/anaconda3/envs/castle/lib/python3.13/site-packages/wandb/sdk/wandb_run.py", line 406, in wrapper
    return func(self, *args, **kwargs)
  File "/opt/anaconda3/envs/castle/lib/python3.13/site-packages/wandb/sdk/wandb_run.py", line 464, in wrapper_fn
    return func(self, *args, **kwargs)
  File "/opt/anaconda3/envs/castle/lib/python3.13/site-packages/wandb/sdk/wandb_run.py", line 1639, in _console_raw_callback
    self._backend.interface.publish_output_raw(name, data)
    ~~~~~~~~~~~~~~~~~~~~~~~~~~~~~~~~~~~~~~~~~~^^^^^^^^^^^^
  File "/opt/anaconda3/envs/castle/lib/python3.13/site-packages/wandb/sdk/interface/interface.py", line 762, in publish_output_raw
    self._publish_output_raw(o)
    ~~~~~~~~~~~~~~~~~~~~~~~~^^^
  File "/opt/anaconda3/envs/castle/lib/python3.13/site-packages/wandb/sdk/interface/interface_shared.py", line 38, in _publish_output_raw
    self._publish(rec)
    ~~~~~~~~~~~~~^^^^^
  File "/opt/anaconda3/envs/castle/lib/python3.13/site-packages/wandb/sdk/interface/interface_sock.py", line 39, in _publish
    self._sock_client.send_record_publish(record)
    ~~~~~~~~~~~~~~~~~~~~~~~~~~~~~~~~~~~~~^^^^^^^^
  File "/opt/anaconda3/envs/castle/lib/python3.13/site-packages/wandb/sdk/lib/sock_client.py", line 174, in send_record_publish
    self.send_server_request(server_req)
    ~~~~~~~~~~~~~~~~~~~~~~~~^^^^^^^^^^^^
  File "/opt/anaconda3/envs/castle/lib/python3.13/site-packages/wandb/sdk/lib/sock_client.py", line 154, in send_server_request
    self._send_message(msg)
    ~~~~~~~~~~~~~~~~~~^^^^^
  File "/opt/anaconda3/envs/castle/lib/python3.13/site-packages/wandb/sdk/lib/sock_client.py", line 151, in _send_message
    self._sendall_with_error_handle(header + data)
    ~~~~~~~~~~~~~~~~~~~~~~~~~~~~~~~^^^^^^^^^^^^^^^
  File "/opt/anaconda3/envs/castle/lib/python3.13/site-packages/wandb/sdk/lib/sock_client.py", line 130, in _sendall_with_error_handle
    sent = self._sock.send(data)
BrokenPipeError: [Errno 32] Broken pipe
2025-06-12 02:37:16,609 ERROR   MainThread:3287 [redirect.py:_on_write():664] [no run ID] error in stderr callback
Traceback (most recent call last):
  File "/opt/anaconda3/envs/castle/lib/python3.13/site-packages/wandb/sdk/lib/redirect.py", line 662, in _on_write
    cb(written_data)
    ~~^^^^^^^^^^^^^^
  File "/opt/anaconda3/envs/castle/lib/python3.13/site-packages/wandb/sdk/wandb_run.py", line 2500, in <lambda>
    lambda data: self._console_raw_callback("stderr", data),
                 ~~~~~~~~~~~~~~~~~~~~~~~~~~^^^^^^^^^^^^^^^^
  File "/opt/anaconda3/envs/castle/lib/python3.13/site-packages/wandb/sdk/wandb_run.py", line 406, in wrapper
    return func(self, *args, **kwargs)
  File "/opt/anaconda3/envs/castle/lib/python3.13/site-packages/wandb/sdk/wandb_run.py", line 464, in wrapper_fn
    return func(self, *args, **kwargs)
  File "/opt/anaconda3/envs/castle/lib/python3.13/site-packages/wandb/sdk/wandb_run.py", line 1639, in _console_raw_callback
    self._backend.interface.publish_output_raw(name, data)
    ~~~~~~~~~~~~~~~~~~~~~~~~~~~~~~~~~~~~~~~~~~^^^^^^^^^^^^
  File "/opt/anaconda3/envs/castle/lib/python3.13/site-packages/wandb/sdk/interface/interface.py", line 762, in publish_output_raw
    self._publish_output_raw(o)
    ~~~~~~~~~~~~~~~~~~~~~~~~^^^
  File "/opt/anaconda3/envs/castle/lib/python3.13/site-packages/wandb/sdk/interface/interface_shared.py", line 38, in _publish_output_raw
    self._publish(rec)
    ~~~~~~~~~~~~~^^^^^
  File "/opt/anaconda3/envs/castle/lib/python3.13/site-packages/wandb/sdk/interface/interface_sock.py", line 39, in _publish
    self._sock_client.send_record_publish(record)
    ~~~~~~~~~~~~~~~~~~~~~~~~~~~~~~~~~~~~~^^^^^^^^
  File "/opt/anaconda3/envs/castle/lib/python3.13/site-packages/wandb/sdk/lib/sock_client.py", line 174, in send_record_publish
    self.send_server_request(server_req)
    ~~~~~~~~~~~~~~~~~~~~~~~~^^^^^^^^^^^^
  File "/opt/anaconda3/envs/castle/lib/python3.13/site-packages/wandb/sdk/lib/sock_client.py", line 154, in send_server_request
    self._send_message(msg)
    ~~~~~~~~~~~~~~~~~~^^^^^
  File "/opt/anaconda3/envs/castle/lib/python3.13/site-packages/wandb/sdk/lib/sock_client.py", line 151, in _send_message
    self._sendall_with_error_handle(header + data)
    ~~~~~~~~~~~~~~~~~~~~~~~~~~~~~~~^^^^^^^^^^^^^^^
  File "/opt/anaconda3/envs/castle/lib/python3.13/site-packages/wandb/sdk/lib/sock_client.py", line 130, in _sendall_with_error_handle
    sent = self._sock.send(data)
BrokenPipeError: [Errno 32] Broken pipe
2025-06-12 02:37:16,610 ERROR   MainThread:3287 [redirect.py:_on_write():664] [no run ID] error in stderr callback
Traceback (most recent call last):
  File "/opt/anaconda3/envs/castle/lib/python3.13/site-packages/wandb/sdk/lib/redirect.py", line 662, in _on_write
    cb(written_data)
    ~~^^^^^^^^^^^^^^
  File "/opt/anaconda3/envs/castle/lib/python3.13/site-packages/wandb/sdk/wandb_run.py", line 2500, in <lambda>
    lambda data: self._console_raw_callback("stderr", data),
                 ~~~~~~~~~~~~~~~~~~~~~~~~~~^^^^^^^^^^^^^^^^
  File "/opt/anaconda3/envs/castle/lib/python3.13/site-packages/wandb/sdk/wandb_run.py", line 406, in wrapper
    return func(self, *args, **kwargs)
  File "/opt/anaconda3/envs/castle/lib/python3.13/site-packages/wandb/sdk/wandb_run.py", line 464, in wrapper_fn
    return func(self, *args, **kwargs)
  File "/opt/anaconda3/envs/castle/lib/python3.13/site-packages/wandb/sdk/wandb_run.py", line 1639, in _console_raw_callback
    self._backend.interface.publish_output_raw(name, data)
    ~~~~~~~~~~~~~~~~~~~~~~~~~~~~~~~~~~~~~~~~~~^^^^^^^^^^^^
  File "/opt/anaconda3/envs/castle/lib/python3.13/site-packages/wandb/sdk/interface/interface.py", line 762, in publish_output_raw
    self._publish_output_raw(o)
    ~~~~~~~~~~~~~~~~~~~~~~~~^^^
  File "/opt/anaconda3/envs/castle/lib/python3.13/site-packages/wandb/sdk/interface/interface_shared.py", line 38, in _publish_output_raw
    self._publish(rec)
    ~~~~~~~~~~~~~^^^^^
  File "/opt/anaconda3/envs/castle/lib/python3.13/site-packages/wandb/sdk/interface/interface_sock.py", line 39, in _publish
    self._sock_client.send_record_publish(record)
    ~~~~~~~~~~~~~~~~~~~~~~~~~~~~~~~~~~~~~^^^^^^^^
  File "/opt/anaconda3/envs/castle/lib/python3.13/site-packages/wandb/sdk/lib/sock_client.py", line 174, in send_record_publish
    self.send_server_request(server_req)
    ~~~~~~~~~~~~~~~~~~~~~~~~^^^^^^^^^^^^
  File "/opt/anaconda3/envs/castle/lib/python3.13/site-packages/wandb/sdk/lib/sock_client.py", line 154, in send_server_request
    self._send_message(msg)
    ~~~~~~~~~~~~~~~~~~^^^^^
  File "/opt/anaconda3/envs/castle/lib/python3.13/site-packages/wandb/sdk/lib/sock_client.py", line 151, in _send_message
    self._sendall_with_error_handle(header + data)
    ~~~~~~~~~~~~~~~~~~~~~~~~~~~~~~~^^^^^^^^^^^^^^^
  File "/opt/anaconda3/envs/castle/lib/python3.13/site-packages/wandb/sdk/lib/sock_client.py", line 130, in _sendall_with_error_handle
    sent = self._sock.send(data)
BrokenPipeError: [Errno 32] Broken pipe
2025-06-12 02:37:16,611 ERROR   MainThread:3287 [redirect.py:_on_write():664] [no run ID] error in stderr callback
Traceback (most recent call last):
  File "/opt/anaconda3/envs/castle/lib/python3.13/site-packages/wandb/sdk/lib/redirect.py", line 662, in _on_write
    cb(written_data)
    ~~^^^^^^^^^^^^^^
  File "/opt/anaconda3/envs/castle/lib/python3.13/site-packages/wandb/sdk/wandb_run.py", line 2500, in <lambda>
    lambda data: self._console_raw_callback("stderr", data),
                 ~~~~~~~~~~~~~~~~~~~~~~~~~~^^^^^^^^^^^^^^^^
  File "/opt/anaconda3/envs/castle/lib/python3.13/site-packages/wandb/sdk/wandb_run.py", line 406, in wrapper
    return func(self, *args, **kwargs)
  File "/opt/anaconda3/envs/castle/lib/python3.13/site-packages/wandb/sdk/wandb_run.py", line 464, in wrapper_fn
    return func(self, *args, **kwargs)
  File "/opt/anaconda3/envs/castle/lib/python3.13/site-packages/wandb/sdk/wandb_run.py", line 1639, in _console_raw_callback
    self._backend.interface.publish_output_raw(name, data)
    ~~~~~~~~~~~~~~~~~~~~~~~~~~~~~~~~~~~~~~~~~~^^^^^^^^^^^^
  File "/opt/anaconda3/envs/castle/lib/python3.13/site-packages/wandb/sdk/interface/interface.py", line 762, in publish_output_raw
    self._publish_output_raw(o)
    ~~~~~~~~~~~~~~~~~~~~~~~~^^^
  File "/opt/anaconda3/envs/castle/lib/python3.13/site-packages/wandb/sdk/interface/interface_shared.py", line 38, in _publish_output_raw
    self._publish(rec)
    ~~~~~~~~~~~~~^^^^^
  File "/opt/anaconda3/envs/castle/lib/python3.13/site-packages/wandb/sdk/interface/interface_sock.py", line 39, in _publish
    self._sock_client.send_record_publish(record)
    ~~~~~~~~~~~~~~~~~~~~~~~~~~~~~~~~~~~~~^^^^^^^^
  File "/opt/anaconda3/envs/castle/lib/python3.13/site-packages/wandb/sdk/lib/sock_client.py", line 174, in send_record_publish
    self.send_server_request(server_req)
    ~~~~~~~~~~~~~~~~~~~~~~~~^^^^^^^^^^^^
  File "/opt/anaconda3/envs/castle/lib/python3.13/site-packages/wandb/sdk/lib/sock_client.py", line 154, in send_server_request
    self._send_message(msg)
    ~~~~~~~~~~~~~~~~~~^^^^^
  File "/opt/anaconda3/envs/castle/lib/python3.13/site-packages/wandb/sdk/lib/sock_client.py", line 151, in _send_message
    self._sendall_with_error_handle(header + data)
    ~~~~~~~~~~~~~~~~~~~~~~~~~~~~~~~^^^^^^^^^^^^^^^
  File "/opt/anaconda3/envs/castle/lib/python3.13/site-packages/wandb/sdk/lib/sock_client.py", line 130, in _sendall_with_error_handle
    sent = self._sock.send(data)
BrokenPipeError: [Errno 32] Broken pipe
2025-06-12 02:37:16,612 ERROR   MainThread:3287 [redirect.py:_on_write():664] [no run ID] error in stderr callback
Traceback (most recent call last):
  File "/opt/anaconda3/envs/castle/lib/python3.13/site-packages/wandb/sdk/lib/redirect.py", line 662, in _on_write
    cb(written_data)
    ~~^^^^^^^^^^^^^^
  File "/opt/anaconda3/envs/castle/lib/python3.13/site-packages/wandb/sdk/wandb_run.py", line 2500, in <lambda>
    lambda data: self._console_raw_callback("stderr", data),
                 ~~~~~~~~~~~~~~~~~~~~~~~~~~^^^^^^^^^^^^^^^^
  File "/opt/anaconda3/envs/castle/lib/python3.13/site-packages/wandb/sdk/wandb_run.py", line 406, in wrapper
    return func(self, *args, **kwargs)
  File "/opt/anaconda3/envs/castle/lib/python3.13/site-packages/wandb/sdk/wandb_run.py", line 464, in wrapper_fn
    return func(self, *args, **kwargs)
  File "/opt/anaconda3/envs/castle/lib/python3.13/site-packages/wandb/sdk/wandb_run.py", line 1639, in _console_raw_callback
    self._backend.interface.publish_output_raw(name, data)
    ~~~~~~~~~~~~~~~~~~~~~~~~~~~~~~~~~~~~~~~~~~^^^^^^^^^^^^
  File "/opt/anaconda3/envs/castle/lib/python3.13/site-packages/wandb/sdk/interface/interface.py", line 762, in publish_output_raw
    self._publish_output_raw(o)
    ~~~~~~~~~~~~~~~~~~~~~~~~^^^
  File "/opt/anaconda3/envs/castle/lib/python3.13/site-packages/wandb/sdk/interface/interface_shared.py", line 38, in _publish_output_raw
    self._publish(rec)
    ~~~~~~~~~~~~~^^^^^
  File "/opt/anaconda3/envs/castle/lib/python3.13/site-packages/wandb/sdk/interface/interface_sock.py", line 39, in _publish
    self._sock_client.send_record_publish(record)
    ~~~~~~~~~~~~~~~~~~~~~~~~~~~~~~~~~~~~~^^^^^^^^
  File "/opt/anaconda3/envs/castle/lib/python3.13/site-packages/wandb/sdk/lib/sock_client.py", line 174, in send_record_publish
    self.send_server_request(server_req)
    ~~~~~~~~~~~~~~~~~~~~~~~~^^^^^^^^^^^^
  File "/opt/anaconda3/envs/castle/lib/python3.13/site-packages/wandb/sdk/lib/sock_client.py", line 154, in send_server_request
    self._send_message(msg)
    ~~~~~~~~~~~~~~~~~~^^^^^
  File "/opt/anaconda3/envs/castle/lib/python3.13/site-packages/wandb/sdk/lib/sock_client.py", line 151, in _send_message
    self._sendall_with_error_handle(header + data)
    ~~~~~~~~~~~~~~~~~~~~~~~~~~~~~~~^^^^^^^^^^^^^^^
  File "/opt/anaconda3/envs/castle/lib/python3.13/site-packages/wandb/sdk/lib/sock_client.py", line 130, in _sendall_with_error_handle
    sent = self._sock.send(data)
BrokenPipeError: [Errno 32] Broken pipe
2025-06-12 02:37:16,612 ERROR   MainThread:3287 [redirect.py:_on_write():664] [no run ID] error in stderr callback
Traceback (most recent call last):
  File "/opt/anaconda3/envs/castle/lib/python3.13/site-packages/wandb/sdk/lib/redirect.py", line 662, in _on_write
    cb(written_data)
    ~~^^^^^^^^^^^^^^
  File "/opt/anaconda3/envs/castle/lib/python3.13/site-packages/wandb/sdk/wandb_run.py", line 2500, in <lambda>
    lambda data: self._console_raw_callback("stderr", data),
                 ~~~~~~~~~~~~~~~~~~~~~~~~~~^^^^^^^^^^^^^^^^
  File "/opt/anaconda3/envs/castle/lib/python3.13/site-packages/wandb/sdk/wandb_run.py", line 406, in wrapper
    return func(self, *args, **kwargs)
  File "/opt/anaconda3/envs/castle/lib/python3.13/site-packages/wandb/sdk/wandb_run.py", line 464, in wrapper_fn
    return func(self, *args, **kwargs)
  File "/opt/anaconda3/envs/castle/lib/python3.13/site-packages/wandb/sdk/wandb_run.py", line 1639, in _console_raw_callback
    self._backend.interface.publish_output_raw(name, data)
    ~~~~~~~~~~~~~~~~~~~~~~~~~~~~~~~~~~~~~~~~~~^^^^^^^^^^^^
  File "/opt/anaconda3/envs/castle/lib/python3.13/site-packages/wandb/sdk/interface/interface.py", line 762, in publish_output_raw
    self._publish_output_raw(o)
    ~~~~~~~~~~~~~~~~~~~~~~~~^^^
  File "/opt/anaconda3/envs/castle/lib/python3.13/site-packages/wandb/sdk/interface/interface_shared.py", line 38, in _publish_output_raw
    self._publish(rec)
    ~~~~~~~~~~~~~^^^^^
  File "/opt/anaconda3/envs/castle/lib/python3.13/site-packages/wandb/sdk/interface/interface_sock.py", line 39, in _publish
    self._sock_client.send_record_publish(record)
    ~~~~~~~~~~~~~~~~~~~~~~~~~~~~~~~~~~~~~^^^^^^^^
  File "/opt/anaconda3/envs/castle/lib/python3.13/site-packages/wandb/sdk/lib/sock_client.py", line 174, in send_record_publish
    self.send_server_request(server_req)
    ~~~~~~~~~~~~~~~~~~~~~~~~^^^^^^^^^^^^
  File "/opt/anaconda3/envs/castle/lib/python3.13/site-packages/wandb/sdk/lib/sock_client.py", line 154, in send_server_request
    self._send_message(msg)
    ~~~~~~~~~~~~~~~~~~^^^^^
  File "/opt/anaconda3/envs/castle/lib/python3.13/site-packages/wandb/sdk/lib/sock_client.py", line 151, in _send_message
    self._sendall_with_error_handle(header + data)
    ~~~~~~~~~~~~~~~~~~~~~~~~~~~~~~~^^^^^^^^^^^^^^^
  File "/opt/anaconda3/envs/castle/lib/python3.13/site-packages/wandb/sdk/lib/sock_client.py", line 130, in _sendall_with_error_handle
    sent = self._sock.send(data)
BrokenPipeError: [Errno 32] Broken pipe
2025-06-12 02:37:16,613 ERROR   MainThread:3287 [redirect.py:_on_write():664] [no run ID] error in stderr callback
Traceback (most recent call last):
  File "/opt/anaconda3/envs/castle/lib/python3.13/site-packages/wandb/sdk/lib/redirect.py", line 662, in _on_write
    cb(written_data)
    ~~^^^^^^^^^^^^^^
  File "/opt/anaconda3/envs/castle/lib/python3.13/site-packages/wandb/sdk/wandb_run.py", line 2500, in <lambda>
    lambda data: self._console_raw_callback("stderr", data),
                 ~~~~~~~~~~~~~~~~~~~~~~~~~~^^^^^^^^^^^^^^^^
  File "/opt/anaconda3/envs/castle/lib/python3.13/site-packages/wandb/sdk/wandb_run.py", line 406, in wrapper
    return func(self, *args, **kwargs)
  File "/opt/anaconda3/envs/castle/lib/python3.13/site-packages/wandb/sdk/wandb_run.py", line 464, in wrapper_fn
    return func(self, *args, **kwargs)
  File "/opt/anaconda3/envs/castle/lib/python3.13/site-packages/wandb/sdk/wandb_run.py", line 1639, in _console_raw_callback
    self._backend.interface.publish_output_raw(name, data)
    ~~~~~~~~~~~~~~~~~~~~~~~~~~~~~~~~~~~~~~~~~~^^^^^^^^^^^^
  File "/opt/anaconda3/envs/castle/lib/python3.13/site-packages/wandb/sdk/interface/interface.py", line 762, in publish_output_raw
    self._publish_output_raw(o)
    ~~~~~~~~~~~~~~~~~~~~~~~~^^^
  File "/opt/anaconda3/envs/castle/lib/python3.13/site-packages/wandb/sdk/interface/interface_shared.py", line 38, in _publish_output_raw
    self._publish(rec)
    ~~~~~~~~~~~~~^^^^^
  File "/opt/anaconda3/envs/castle/lib/python3.13/site-packages/wandb/sdk/interface/interface_sock.py", line 39, in _publish
    self._sock_client.send_record_publish(record)
    ~~~~~~~~~~~~~~~~~~~~~~~~~~~~~~~~~~~~~^^^^^^^^
  File "/opt/anaconda3/envs/castle/lib/python3.13/site-packages/wandb/sdk/lib/sock_client.py", line 174, in send_record_publish
    self.send_server_request(server_req)
    ~~~~~~~~~~~~~~~~~~~~~~~~^^^^^^^^^^^^
  File "/opt/anaconda3/envs/castle/lib/python3.13/site-packages/wandb/sdk/lib/sock_client.py", line 154, in send_server_request
    self._send_message(msg)
    ~~~~~~~~~~~~~~~~~~^^^^^
  File "/opt/anaconda3/envs/castle/lib/python3.13/site-packages/wandb/sdk/lib/sock_client.py", line 151, in _send_message
    self._sendall_with_error_handle(header + data)
    ~~~~~~~~~~~~~~~~~~~~~~~~~~~~~~~^^^^^^^^^^^^^^^
  File "/opt/anaconda3/envs/castle/lib/python3.13/site-packages/wandb/sdk/lib/sock_client.py", line 130, in _sendall_with_error_handle
    sent = self._sock.send(data)
BrokenPipeError: [Errno 32] Broken pipe
2025-06-12 02:37:16,614 ERROR   MainThread:3287 [redirect.py:_on_write():664] [no run ID] error in stderr callback
Traceback (most recent call last):
  File "/opt/anaconda3/envs/castle/lib/python3.13/site-packages/wandb/sdk/lib/redirect.py", line 662, in _on_write
    cb(written_data)
    ~~^^^^^^^^^^^^^^
  File "/opt/anaconda3/envs/castle/lib/python3.13/site-packages/wandb/sdk/wandb_run.py", line 2500, in <lambda>
    lambda data: self._console_raw_callback("stderr", data),
                 ~~~~~~~~~~~~~~~~~~~~~~~~~~^^^^^^^^^^^^^^^^
  File "/opt/anaconda3/envs/castle/lib/python3.13/site-packages/wandb/sdk/wandb_run.py", line 406, in wrapper
    return func(self, *args, **kwargs)
  File "/opt/anaconda3/envs/castle/lib/python3.13/site-packages/wandb/sdk/wandb_run.py", line 464, in wrapper_fn
    return func(self, *args, **kwargs)
  File "/opt/anaconda3/envs/castle/lib/python3.13/site-packages/wandb/sdk/wandb_run.py", line 1639, in _console_raw_callback
    self._backend.interface.publish_output_raw(name, data)
    ~~~~~~~~~~~~~~~~~~~~~~~~~~~~~~~~~~~~~~~~~~^^^^^^^^^^^^
  File "/opt/anaconda3/envs/castle/lib/python3.13/site-packages/wandb/sdk/interface/interface.py", line 762, in publish_output_raw
    self._publish_output_raw(o)
    ~~~~~~~~~~~~~~~~~~~~~~~~^^^
  File "/opt/anaconda3/envs/castle/lib/python3.13/site-packages/wandb/sdk/interface/interface_shared.py", line 38, in _publish_output_raw
    self._publish(rec)
    ~~~~~~~~~~~~~^^^^^
  File "/opt/anaconda3/envs/castle/lib/python3.13/site-packages/wandb/sdk/interface/interface_sock.py", line 39, in _publish
    self._sock_client.send_record_publish(record)
    ~~~~~~~~~~~~~~~~~~~~~~~~~~~~~~~~~~~~~^^^^^^^^
  File "/opt/anaconda3/envs/castle/lib/python3.13/site-packages/wandb/sdk/lib/sock_client.py", line 174, in send_record_publish
    self.send_server_request(server_req)
    ~~~~~~~~~~~~~~~~~~~~~~~~^^^^^^^^^^^^
  File "/opt/anaconda3/envs/castle/lib/python3.13/site-packages/wandb/sdk/lib/sock_client.py", line 154, in send_server_request
    self._send_message(msg)
    ~~~~~~~~~~~~~~~~~~^^^^^
  File "/opt/anaconda3/envs/castle/lib/python3.13/site-packages/wandb/sdk/lib/sock_client.py", line 151, in _send_message
    self._sendall_with_error_handle(header + data)
    ~~~~~~~~~~~~~~~~~~~~~~~~~~~~~~~^^^^^^^^^^^^^^^
  File "/opt/anaconda3/envs/castle/lib/python3.13/site-packages/wandb/sdk/lib/sock_client.py", line 130, in _sendall_with_error_handle
    sent = self._sock.send(data)
BrokenPipeError: [Errno 32] Broken pipe
2025-06-12 02:37:16,614 ERROR   MainThread:3287 [redirect.py:_on_write():664] [no run ID] error in stderr callback
Traceback (most recent call last):
  File "/opt/anaconda3/envs/castle/lib/python3.13/site-packages/wandb/sdk/lib/redirect.py", line 662, in _on_write
    cb(written_data)
    ~~^^^^^^^^^^^^^^
  File "/opt/anaconda3/envs/castle/lib/python3.13/site-packages/wandb/sdk/wandb_run.py", line 2500, in <lambda>
    lambda data: self._console_raw_callback("stderr", data),
                 ~~~~~~~~~~~~~~~~~~~~~~~~~~^^^^^^^^^^^^^^^^
  File "/opt/anaconda3/envs/castle/lib/python3.13/site-packages/wandb/sdk/wandb_run.py", line 406, in wrapper
    return func(self, *args, **kwargs)
  File "/opt/anaconda3/envs/castle/lib/python3.13/site-packages/wandb/sdk/wandb_run.py", line 464, in wrapper_fn
    return func(self, *args, **kwargs)
  File "/opt/anaconda3/envs/castle/lib/python3.13/site-packages/wandb/sdk/wandb_run.py", line 1639, in _console_raw_callback
    self._backend.interface.publish_output_raw(name, data)
    ~~~~~~~~~~~~~~~~~~~~~~~~~~~~~~~~~~~~~~~~~~^^^^^^^^^^^^
  File "/opt/anaconda3/envs/castle/lib/python3.13/site-packages/wandb/sdk/interface/interface.py", line 762, in publish_output_raw
    self._publish_output_raw(o)
    ~~~~~~~~~~~~~~~~~~~~~~~~^^^
  File "/opt/anaconda3/envs/castle/lib/python3.13/site-packages/wandb/sdk/interface/interface_shared.py", line 38, in _publish_output_raw
    self._publish(rec)
    ~~~~~~~~~~~~~^^^^^
  File "/opt/anaconda3/envs/castle/lib/python3.13/site-packages/wandb/sdk/interface/interface_sock.py", line 39, in _publish
    self._sock_client.send_record_publish(record)
    ~~~~~~~~~~~~~~~~~~~~~~~~~~~~~~~~~~~~~^^^^^^^^
  File "/opt/anaconda3/envs/castle/lib/python3.13/site-packages/wandb/sdk/lib/sock_client.py", line 174, in send_record_publish
    self.send_server_request(server_req)
    ~~~~~~~~~~~~~~~~~~~~~~~~^^^^^^^^^^^^
  File "/opt/anaconda3/envs/castle/lib/python3.13/site-packages/wandb/sdk/lib/sock_client.py", line 154, in send_server_request
    self._send_message(msg)
    ~~~~~~~~~~~~~~~~~~^^^^^
  File "/opt/anaconda3/envs/castle/lib/python3.13/site-packages/wandb/sdk/lib/sock_client.py", line 151, in _send_message
    self._sendall_with_error_handle(header + data)
    ~~~~~~~~~~~~~~~~~~~~~~~~~~~~~~~^^^^^^^^^^^^^^^
  File "/opt/anaconda3/envs/castle/lib/python3.13/site-packages/wandb/sdk/lib/sock_client.py", line 130, in _sendall_with_error_handle
    sent = self._sock.send(data)
BrokenPipeError: [Errno 32] Broken pipe
2025-06-12 02:37:16,615 ERROR   MainThread:3287 [redirect.py:_on_write():664] [no run ID] error in stderr callback
Traceback (most recent call last):
  File "/opt/anaconda3/envs/castle/lib/python3.13/site-packages/wandb/sdk/lib/redirect.py", line 662, in _on_write
    cb(written_data)
    ~~^^^^^^^^^^^^^^
  File "/opt/anaconda3/envs/castle/lib/python3.13/site-packages/wandb/sdk/wandb_run.py", line 2500, in <lambda>
    lambda data: self._console_raw_callback("stderr", data),
                 ~~~~~~~~~~~~~~~~~~~~~~~~~~^^^^^^^^^^^^^^^^
  File "/opt/anaconda3/envs/castle/lib/python3.13/site-packages/wandb/sdk/wandb_run.py", line 406, in wrapper
    return func(self, *args, **kwargs)
  File "/opt/anaconda3/envs/castle/lib/python3.13/site-packages/wandb/sdk/wandb_run.py", line 464, in wrapper_fn
    return func(self, *args, **kwargs)
  File "/opt/anaconda3/envs/castle/lib/python3.13/site-packages/wandb/sdk/wandb_run.py", line 1639, in _console_raw_callback
    self._backend.interface.publish_output_raw(name, data)
    ~~~~~~~~~~~~~~~~~~~~~~~~~~~~~~~~~~~~~~~~~~^^^^^^^^^^^^
  File "/opt/anaconda3/envs/castle/lib/python3.13/site-packages/wandb/sdk/interface/interface.py", line 762, in publish_output_raw
    self._publish_output_raw(o)
    ~~~~~~~~~~~~~~~~~~~~~~~~^^^
  File "/opt/anaconda3/envs/castle/lib/python3.13/site-packages/wandb/sdk/interface/interface_shared.py", line 38, in _publish_output_raw
    self._publish(rec)
    ~~~~~~~~~~~~~^^^^^
  File "/opt/anaconda3/envs/castle/lib/python3.13/site-packages/wandb/sdk/interface/interface_sock.py", line 39, in _publish
    self._sock_client.send_record_publish(record)
    ~~~~~~~~~~~~~~~~~~~~~~~~~~~~~~~~~~~~~^^^^^^^^
  File "/opt/anaconda3/envs/castle/lib/python3.13/site-packages/wandb/sdk/lib/sock_client.py", line 174, in send_record_publish
    self.send_server_request(server_req)
    ~~~~~~~~~~~~~~~~~~~~~~~~^^^^^^^^^^^^
  File "/opt/anaconda3/envs/castle/lib/python3.13/site-packages/wandb/sdk/lib/sock_client.py", line 154, in send_server_request
    self._send_message(msg)
    ~~~~~~~~~~~~~~~~~~^^^^^
  File "/opt/anaconda3/envs/castle/lib/python3.13/site-packages/wandb/sdk/lib/sock_client.py", line 151, in _send_message
    self._sendall_with_error_handle(header + data)
    ~~~~~~~~~~~~~~~~~~~~~~~~~~~~~~~^^^^^^^^^^^^^^^
  File "/opt/anaconda3/envs/castle/lib/python3.13/site-packages/wandb/sdk/lib/sock_client.py", line 130, in _sendall_with_error_handle
    sent = self._sock.send(data)
BrokenPipeError: [Errno 32] Broken pipe
2025-06-12 02:37:16,615 ERROR   MainThread:3287 [redirect.py:_on_write():664] [no run ID] error in stderr callback
Traceback (most recent call last):
  File "/opt/anaconda3/envs/castle/lib/python3.13/site-packages/wandb/sdk/lib/redirect.py", line 662, in _on_write
    cb(written_data)
    ~~^^^^^^^^^^^^^^
  File "/opt/anaconda3/envs/castle/lib/python3.13/site-packages/wandb/sdk/wandb_run.py", line 2500, in <lambda>
    lambda data: self._console_raw_callback("stderr", data),
                 ~~~~~~~~~~~~~~~~~~~~~~~~~~^^^^^^^^^^^^^^^^
  File "/opt/anaconda3/envs/castle/lib/python3.13/site-packages/wandb/sdk/wandb_run.py", line 406, in wrapper
    return func(self, *args, **kwargs)
  File "/opt/anaconda3/envs/castle/lib/python3.13/site-packages/wandb/sdk/wandb_run.py", line 464, in wrapper_fn
    return func(self, *args, **kwargs)
  File "/opt/anaconda3/envs/castle/lib/python3.13/site-packages/wandb/sdk/wandb_run.py", line 1639, in _console_raw_callback
    self._backend.interface.publish_output_raw(name, data)
    ~~~~~~~~~~~~~~~~~~~~~~~~~~~~~~~~~~~~~~~~~~^^^^^^^^^^^^
  File "/opt/anaconda3/envs/castle/lib/python3.13/site-packages/wandb/sdk/interface/interface.py", line 762, in publish_output_raw
    self._publish_output_raw(o)
    ~~~~~~~~~~~~~~~~~~~~~~~~^^^
  File "/opt/anaconda3/envs/castle/lib/python3.13/site-packages/wandb/sdk/interface/interface_shared.py", line 38, in _publish_output_raw
    self._publish(rec)
    ~~~~~~~~~~~~~^^^^^
  File "/opt/anaconda3/envs/castle/lib/python3.13/site-packages/wandb/sdk/interface/interface_sock.py", line 39, in _publish
    self._sock_client.send_record_publish(record)
    ~~~~~~~~~~~~~~~~~~~~~~~~~~~~~~~~~~~~~^^^^^^^^
  File "/opt/anaconda3/envs/castle/lib/python3.13/site-packages/wandb/sdk/lib/sock_client.py", line 174, in send_record_publish
    self.send_server_request(server_req)
    ~~~~~~~~~~~~~~~~~~~~~~~~^^^^^^^^^^^^
  File "/opt/anaconda3/envs/castle/lib/python3.13/site-packages/wandb/sdk/lib/sock_client.py", line 154, in send_server_request
    self._send_message(msg)
    ~~~~~~~~~~~~~~~~~~^^^^^
  File "/opt/anaconda3/envs/castle/lib/python3.13/site-packages/wandb/sdk/lib/sock_client.py", line 151, in _send_message
    self._sendall_with_error_handle(header + data)
    ~~~~~~~~~~~~~~~~~~~~~~~~~~~~~~~^^^^^^^^^^^^^^^
  File "/opt/anaconda3/envs/castle/lib/python3.13/site-packages/wandb/sdk/lib/sock_client.py", line 130, in _sendall_with_error_handle
    sent = self._sock.send(data)
BrokenPipeError: [Errno 32] Broken pipe
2025-06-12 02:37:16,616 ERROR   MainThread:3287 [redirect.py:_on_write():664] [no run ID] error in stderr callback
Traceback (most recent call last):
  File "/opt/anaconda3/envs/castle/lib/python3.13/site-packages/wandb/sdk/lib/redirect.py", line 662, in _on_write
    cb(written_data)
    ~~^^^^^^^^^^^^^^
  File "/opt/anaconda3/envs/castle/lib/python3.13/site-packages/wandb/sdk/wandb_run.py", line 2500, in <lambda>
    lambda data: self._console_raw_callback("stderr", data),
                 ~~~~~~~~~~~~~~~~~~~~~~~~~~^^^^^^^^^^^^^^^^
  File "/opt/anaconda3/envs/castle/lib/python3.13/site-packages/wandb/sdk/wandb_run.py", line 406, in wrapper
    return func(self, *args, **kwargs)
  File "/opt/anaconda3/envs/castle/lib/python3.13/site-packages/wandb/sdk/wandb_run.py", line 464, in wrapper_fn
    return func(self, *args, **kwargs)
  File "/opt/anaconda3/envs/castle/lib/python3.13/site-packages/wandb/sdk/wandb_run.py", line 1639, in _console_raw_callback
    self._backend.interface.publish_output_raw(name, data)
    ~~~~~~~~~~~~~~~~~~~~~~~~~~~~~~~~~~~~~~~~~~^^^^^^^^^^^^
  File "/opt/anaconda3/envs/castle/lib/python3.13/site-packages/wandb/sdk/interface/interface.py", line 762, in publish_output_raw
    self._publish_output_raw(o)
    ~~~~~~~~~~~~~~~~~~~~~~~~^^^
  File "/opt/anaconda3/envs/castle/lib/python3.13/site-packages/wandb/sdk/interface/interface_shared.py", line 38, in _publish_output_raw
    self._publish(rec)
    ~~~~~~~~~~~~~^^^^^
  File "/opt/anaconda3/envs/castle/lib/python3.13/site-packages/wandb/sdk/interface/interface_sock.py", line 39, in _publish
    self._sock_client.send_record_publish(record)
    ~~~~~~~~~~~~~~~~~~~~~~~~~~~~~~~~~~~~~^^^^^^^^
  File "/opt/anaconda3/envs/castle/lib/python3.13/site-packages/wandb/sdk/lib/sock_client.py", line 174, in send_record_publish
    self.send_server_request(server_req)
    ~~~~~~~~~~~~~~~~~~~~~~~~^^^^^^^^^^^^
  File "/opt/anaconda3/envs/castle/lib/python3.13/site-packages/wandb/sdk/lib/sock_client.py", line 154, in send_server_request
    self._send_message(msg)
    ~~~~~~~~~~~~~~~~~~^^^^^
  File "/opt/anaconda3/envs/castle/lib/python3.13/site-packages/wandb/sdk/lib/sock_client.py", line 151, in _send_message
    self._sendall_with_error_handle(header + data)
    ~~~~~~~~~~~~~~~~~~~~~~~~~~~~~~~^^^^^^^^^^^^^^^
  File "/opt/anaconda3/envs/castle/lib/python3.13/site-packages/wandb/sdk/lib/sock_client.py", line 130, in _sendall_with_error_handle
    sent = self._sock.send(data)
BrokenPipeError: [Errno 32] Broken pipe
2025-06-12 02:37:16,616 ERROR   MainThread:3287 [redirect.py:_on_write():664] [no run ID] error in stderr callback
Traceback (most recent call last):
  File "/opt/anaconda3/envs/castle/lib/python3.13/site-packages/wandb/sdk/lib/redirect.py", line 662, in _on_write
    cb(written_data)
    ~~^^^^^^^^^^^^^^
  File "/opt/anaconda3/envs/castle/lib/python3.13/site-packages/wandb/sdk/wandb_run.py", line 2500, in <lambda>
    lambda data: self._console_raw_callback("stderr", data),
                 ~~~~~~~~~~~~~~~~~~~~~~~~~~^^^^^^^^^^^^^^^^
  File "/opt/anaconda3/envs/castle/lib/python3.13/site-packages/wandb/sdk/wandb_run.py", line 406, in wrapper
    return func(self, *args, **kwargs)
  File "/opt/anaconda3/envs/castle/lib/python3.13/site-packages/wandb/sdk/wandb_run.py", line 464, in wrapper_fn
    return func(self, *args, **kwargs)
  File "/opt/anaconda3/envs/castle/lib/python3.13/site-packages/wandb/sdk/wandb_run.py", line 1639, in _console_raw_callback
    self._backend.interface.publish_output_raw(name, data)
    ~~~~~~~~~~~~~~~~~~~~~~~~~~~~~~~~~~~~~~~~~~^^^^^^^^^^^^
  File "/opt/anaconda3/envs/castle/lib/python3.13/site-packages/wandb/sdk/interface/interface.py", line 762, in publish_output_raw
    self._publish_output_raw(o)
    ~~~~~~~~~~~~~~~~~~~~~~~~^^^
  File "/opt/anaconda3/envs/castle/lib/python3.13/site-packages/wandb/sdk/interface/interface_shared.py", line 38, in _publish_output_raw
    self._publish(rec)
    ~~~~~~~~~~~~~^^^^^
  File "/opt/anaconda3/envs/castle/lib/python3.13/site-packages/wandb/sdk/interface/interface_sock.py", line 39, in _publish
    self._sock_client.send_record_publish(record)
    ~~~~~~~~~~~~~~~~~~~~~~~~~~~~~~~~~~~~~^^^^^^^^
  File "/opt/anaconda3/envs/castle/lib/python3.13/site-packages/wandb/sdk/lib/sock_client.py", line 174, in send_record_publish
    self.send_server_request(server_req)
    ~~~~~~~~~~~~~~~~~~~~~~~~^^^^^^^^^^^^
  File "/opt/anaconda3/envs/castle/lib/python3.13/site-packages/wandb/sdk/lib/sock_client.py", line 154, in send_server_request
    self._send_message(msg)
    ~~~~~~~~~~~~~~~~~~^^^^^
  File "/opt/anaconda3/envs/castle/lib/python3.13/site-packages/wandb/sdk/lib/sock_client.py", line 151, in _send_message
    self._sendall_with_error_handle(header + data)
    ~~~~~~~~~~~~~~~~~~~~~~~~~~~~~~~^^^^^^^^^^^^^^^
  File "/opt/anaconda3/envs/castle/lib/python3.13/site-packages/wandb/sdk/lib/sock_client.py", line 130, in _sendall_with_error_handle
    sent = self._sock.send(data)
BrokenPipeError: [Errno 32] Broken pipe
2025-06-12 02:37:16,617 ERROR   MainThread:3287 [redirect.py:_on_write():664] [no run ID] error in stderr callback
Traceback (most recent call last):
  File "/opt/anaconda3/envs/castle/lib/python3.13/site-packages/wandb/sdk/lib/redirect.py", line 662, in _on_write
    cb(written_data)
    ~~^^^^^^^^^^^^^^
  File "/opt/anaconda3/envs/castle/lib/python3.13/site-packages/wandb/sdk/wandb_run.py", line 2500, in <lambda>
    lambda data: self._console_raw_callback("stderr", data),
                 ~~~~~~~~~~~~~~~~~~~~~~~~~~^^^^^^^^^^^^^^^^
  File "/opt/anaconda3/envs/castle/lib/python3.13/site-packages/wandb/sdk/wandb_run.py", line 406, in wrapper
    return func(self, *args, **kwargs)
  File "/opt/anaconda3/envs/castle/lib/python3.13/site-packages/wandb/sdk/wandb_run.py", line 464, in wrapper_fn
    return func(self, *args, **kwargs)
  File "/opt/anaconda3/envs/castle/lib/python3.13/site-packages/wandb/sdk/wandb_run.py", line 1639, in _console_raw_callback
    self._backend.interface.publish_output_raw(name, data)
    ~~~~~~~~~~~~~~~~~~~~~~~~~~~~~~~~~~~~~~~~~~^^^^^^^^^^^^
  File "/opt/anaconda3/envs/castle/lib/python3.13/site-packages/wandb/sdk/interface/interface.py", line 762, in publish_output_raw
    self._publish_output_raw(o)
    ~~~~~~~~~~~~~~~~~~~~~~~~^^^
  File "/opt/anaconda3/envs/castle/lib/python3.13/site-packages/wandb/sdk/interface/interface_shared.py", line 38, in _publish_output_raw
    self._publish(rec)
    ~~~~~~~~~~~~~^^^^^
  File "/opt/anaconda3/envs/castle/lib/python3.13/site-packages/wandb/sdk/interface/interface_sock.py", line 39, in _publish
    self._sock_client.send_record_publish(record)
    ~~~~~~~~~~~~~~~~~~~~~~~~~~~~~~~~~~~~~^^^^^^^^
  File "/opt/anaconda3/envs/castle/lib/python3.13/site-packages/wandb/sdk/lib/sock_client.py", line 174, in send_record_publish
    self.send_server_request(server_req)
    ~~~~~~~~~~~~~~~~~~~~~~~~^^^^^^^^^^^^
  File "/opt/anaconda3/envs/castle/lib/python3.13/site-packages/wandb/sdk/lib/sock_client.py", line 154, in send_server_request
    self._send_message(msg)
    ~~~~~~~~~~~~~~~~~~^^^^^
  File "/opt/anaconda3/envs/castle/lib/python3.13/site-packages/wandb/sdk/lib/sock_client.py", line 151, in _send_message
    self._sendall_with_error_handle(header + data)
    ~~~~~~~~~~~~~~~~~~~~~~~~~~~~~~~^^^^^^^^^^^^^^^
  File "/opt/anaconda3/envs/castle/lib/python3.13/site-packages/wandb/sdk/lib/sock_client.py", line 130, in _sendall_with_error_handle
    sent = self._sock.send(data)
BrokenPipeError: [Errno 32] Broken pipe
2025-06-12 02:37:16,617 ERROR   MainThread:3287 [redirect.py:_on_write():664] [no run ID] error in stderr callback
Traceback (most recent call last):
  File "/opt/anaconda3/envs/castle/lib/python3.13/site-packages/wandb/sdk/lib/redirect.py", line 662, in _on_write
    cb(written_data)
    ~~^^^^^^^^^^^^^^
  File "/opt/anaconda3/envs/castle/lib/python3.13/site-packages/wandb/sdk/wandb_run.py", line 2500, in <lambda>
    lambda data: self._console_raw_callback("stderr", data),
                 ~~~~~~~~~~~~~~~~~~~~~~~~~~^^^^^^^^^^^^^^^^
  File "/opt/anaconda3/envs/castle/lib/python3.13/site-packages/wandb/sdk/wandb_run.py", line 406, in wrapper
    return func(self, *args, **kwargs)
  File "/opt/anaconda3/envs/castle/lib/python3.13/site-packages/wandb/sdk/wandb_run.py", line 464, in wrapper_fn
    return func(self, *args, **kwargs)
  File "/opt/anaconda3/envs/castle/lib/python3.13/site-packages/wandb/sdk/wandb_run.py", line 1639, in _console_raw_callback
    self._backend.interface.publish_output_raw(name, data)
    ~~~~~~~~~~~~~~~~~~~~~~~~~~~~~~~~~~~~~~~~~~^^^^^^^^^^^^
  File "/opt/anaconda3/envs/castle/lib/python3.13/site-packages/wandb/sdk/interface/interface.py", line 762, in publish_output_raw
    self._publish_output_raw(o)
    ~~~~~~~~~~~~~~~~~~~~~~~~^^^
  File "/opt/anaconda3/envs/castle/lib/python3.13/site-packages/wandb/sdk/interface/interface_shared.py", line 38, in _publish_output_raw
    self._publish(rec)
    ~~~~~~~~~~~~~^^^^^
  File "/opt/anaconda3/envs/castle/lib/python3.13/site-packages/wandb/sdk/interface/interface_sock.py", line 39, in _publish
    self._sock_client.send_record_publish(record)
    ~~~~~~~~~~~~~~~~~~~~~~~~~~~~~~~~~~~~~^^^^^^^^
  File "/opt/anaconda3/envs/castle/lib/python3.13/site-packages/wandb/sdk/lib/sock_client.py", line 174, in send_record_publish
    self.send_server_request(server_req)
    ~~~~~~~~~~~~~~~~~~~~~~~~^^^^^^^^^^^^
  File "/opt/anaconda3/envs/castle/lib/python3.13/site-packages/wandb/sdk/lib/sock_client.py", line 154, in send_server_request
    self._send_message(msg)
    ~~~~~~~~~~~~~~~~~~^^^^^
  File "/opt/anaconda3/envs/castle/lib/python3.13/site-packages/wandb/sdk/lib/sock_client.py", line 151, in _send_message
    self._sendall_with_error_handle(header + data)
    ~~~~~~~~~~~~~~~~~~~~~~~~~~~~~~~^^^^^^^^^^^^^^^
  File "/opt/anaconda3/envs/castle/lib/python3.13/site-packages/wandb/sdk/lib/sock_client.py", line 130, in _sendall_with_error_handle
    sent = self._sock.send(data)
BrokenPipeError: [Errno 32] Broken pipe
2025-06-12 02:37:16,618 ERROR   MainThread:3287 [redirect.py:_on_write():664] [no run ID] error in stderr callback
Traceback (most recent call last):
  File "/opt/anaconda3/envs/castle/lib/python3.13/site-packages/wandb/sdk/lib/redirect.py", line 662, in _on_write
    cb(written_data)
    ~~^^^^^^^^^^^^^^
  File "/opt/anaconda3/envs/castle/lib/python3.13/site-packages/wandb/sdk/wandb_run.py", line 2500, in <lambda>
    lambda data: self._console_raw_callback("stderr", data),
                 ~~~~~~~~~~~~~~~~~~~~~~~~~~^^^^^^^^^^^^^^^^
  File "/opt/anaconda3/envs/castle/lib/python3.13/site-packages/wandb/sdk/wandb_run.py", line 406, in wrapper
    return func(self, *args, **kwargs)
  File "/opt/anaconda3/envs/castle/lib/python3.13/site-packages/wandb/sdk/wandb_run.py", line 464, in wrapper_fn
    return func(self, *args, **kwargs)
  File "/opt/anaconda3/envs/castle/lib/python3.13/site-packages/wandb/sdk/wandb_run.py", line 1639, in _console_raw_callback
    self._backend.interface.publish_output_raw(name, data)
    ~~~~~~~~~~~~~~~~~~~~~~~~~~~~~~~~~~~~~~~~~~^^^^^^^^^^^^
  File "/opt/anaconda3/envs/castle/lib/python3.13/site-packages/wandb/sdk/interface/interface.py", line 762, in publish_output_raw
    self._publish_output_raw(o)
    ~~~~~~~~~~~~~~~~~~~~~~~~^^^
  File "/opt/anaconda3/envs/castle/lib/python3.13/site-packages/wandb/sdk/interface/interface_shared.py", line 38, in _publish_output_raw
    self._publish(rec)
    ~~~~~~~~~~~~~^^^^^
  File "/opt/anaconda3/envs/castle/lib/python3.13/site-packages/wandb/sdk/interface/interface_sock.py", line 39, in _publish
    self._sock_client.send_record_publish(record)
    ~~~~~~~~~~~~~~~~~~~~~~~~~~~~~~~~~~~~~^^^^^^^^
  File "/opt/anaconda3/envs/castle/lib/python3.13/site-packages/wandb/sdk/lib/sock_client.py", line 174, in send_record_publish
    self.send_server_request(server_req)
    ~~~~~~~~~~~~~~~~~~~~~~~~^^^^^^^^^^^^
  File "/opt/anaconda3/envs/castle/lib/python3.13/site-packages/wandb/sdk/lib/sock_client.py", line 154, in send_server_request
    self._send_message(msg)
    ~~~~~~~~~~~~~~~~~~^^^^^
  File "/opt/anaconda3/envs/castle/lib/python3.13/site-packages/wandb/sdk/lib/sock_client.py", line 151, in _send_message
    self._sendall_with_error_handle(header + data)
    ~~~~~~~~~~~~~~~~~~~~~~~~~~~~~~~^^^^^^^^^^^^^^^
  File "/opt/anaconda3/envs/castle/lib/python3.13/site-packages/wandb/sdk/lib/sock_client.py", line 130, in _sendall_with_error_handle
    sent = self._sock.send(data)
BrokenPipeError: [Errno 32] Broken pipe
2025-06-12 02:37:16,618 ERROR   MainThread:3287 [redirect.py:_on_write():664] [no run ID] error in stderr callback
Traceback (most recent call last):
  File "/opt/anaconda3/envs/castle/lib/python3.13/site-packages/wandb/sdk/lib/redirect.py", line 662, in _on_write
    cb(written_data)
    ~~^^^^^^^^^^^^^^
  File "/opt/anaconda3/envs/castle/lib/python3.13/site-packages/wandb/sdk/wandb_run.py", line 2500, in <lambda>
    lambda data: self._console_raw_callback("stderr", data),
                 ~~~~~~~~~~~~~~~~~~~~~~~~~~^^^^^^^^^^^^^^^^
  File "/opt/anaconda3/envs/castle/lib/python3.13/site-packages/wandb/sdk/wandb_run.py", line 406, in wrapper
    return func(self, *args, **kwargs)
  File "/opt/anaconda3/envs/castle/lib/python3.13/site-packages/wandb/sdk/wandb_run.py", line 464, in wrapper_fn
    return func(self, *args, **kwargs)
  File "/opt/anaconda3/envs/castle/lib/python3.13/site-packages/wandb/sdk/wandb_run.py", line 1639, in _console_raw_callback
    self._backend.interface.publish_output_raw(name, data)
    ~~~~~~~~~~~~~~~~~~~~~~~~~~~~~~~~~~~~~~~~~~^^^^^^^^^^^^
  File "/opt/anaconda3/envs/castle/lib/python3.13/site-packages/wandb/sdk/interface/interface.py", line 762, in publish_output_raw
    self._publish_output_raw(o)
    ~~~~~~~~~~~~~~~~~~~~~~~~^^^
  File "/opt/anaconda3/envs/castle/lib/python3.13/site-packages/wandb/sdk/interface/interface_shared.py", line 38, in _publish_output_raw
    self._publish(rec)
    ~~~~~~~~~~~~~^^^^^
  File "/opt/anaconda3/envs/castle/lib/python3.13/site-packages/wandb/sdk/interface/interface_sock.py", line 39, in _publish
    self._sock_client.send_record_publish(record)
    ~~~~~~~~~~~~~~~~~~~~~~~~~~~~~~~~~~~~~^^^^^^^^
  File "/opt/anaconda3/envs/castle/lib/python3.13/site-packages/wandb/sdk/lib/sock_client.py", line 174, in send_record_publish
    self.send_server_request(server_req)
    ~~~~~~~~~~~~~~~~~~~~~~~~^^^^^^^^^^^^
  File "/opt/anaconda3/envs/castle/lib/python3.13/site-packages/wandb/sdk/lib/sock_client.py", line 154, in send_server_request
    self._send_message(msg)
    ~~~~~~~~~~~~~~~~~~^^^^^
  File "/opt/anaconda3/envs/castle/lib/python3.13/site-packages/wandb/sdk/lib/sock_client.py", line 151, in _send_message
    self._sendall_with_error_handle(header + data)
    ~~~~~~~~~~~~~~~~~~~~~~~~~~~~~~~^^^^^^^^^^^^^^^
  File "/opt/anaconda3/envs/castle/lib/python3.13/site-packages/wandb/sdk/lib/sock_client.py", line 130, in _sendall_with_error_handle
    sent = self._sock.send(data)
BrokenPipeError: [Errno 32] Broken pipe
2025-06-12 02:37:16,619 ERROR   MainThread:3287 [redirect.py:_on_write():664] [no run ID] error in stderr callback
Traceback (most recent call last):
  File "/opt/anaconda3/envs/castle/lib/python3.13/site-packages/wandb/sdk/lib/redirect.py", line 662, in _on_write
    cb(written_data)
    ~~^^^^^^^^^^^^^^
  File "/opt/anaconda3/envs/castle/lib/python3.13/site-packages/wandb/sdk/wandb_run.py", line 2500, in <lambda>
    lambda data: self._console_raw_callback("stderr", data),
                 ~~~~~~~~~~~~~~~~~~~~~~~~~~^^^^^^^^^^^^^^^^
  File "/opt/anaconda3/envs/castle/lib/python3.13/site-packages/wandb/sdk/wandb_run.py", line 406, in wrapper
    return func(self, *args, **kwargs)
  File "/opt/anaconda3/envs/castle/lib/python3.13/site-packages/wandb/sdk/wandb_run.py", line 464, in wrapper_fn
    return func(self, *args, **kwargs)
  File "/opt/anaconda3/envs/castle/lib/python3.13/site-packages/wandb/sdk/wandb_run.py", line 1639, in _console_raw_callback
    self._backend.interface.publish_output_raw(name, data)
    ~~~~~~~~~~~~~~~~~~~~~~~~~~~~~~~~~~~~~~~~~~^^^^^^^^^^^^
  File "/opt/anaconda3/envs/castle/lib/python3.13/site-packages/wandb/sdk/interface/interface.py", line 762, in publish_output_raw
    self._publish_output_raw(o)
    ~~~~~~~~~~~~~~~~~~~~~~~~^^^
  File "/opt/anaconda3/envs/castle/lib/python3.13/site-packages/wandb/sdk/interface/interface_shared.py", line 38, in _publish_output_raw
    self._publish(rec)
    ~~~~~~~~~~~~~^^^^^
  File "/opt/anaconda3/envs/castle/lib/python3.13/site-packages/wandb/sdk/interface/interface_sock.py", line 39, in _publish
    self._sock_client.send_record_publish(record)
    ~~~~~~~~~~~~~~~~~~~~~~~~~~~~~~~~~~~~~^^^^^^^^
  File "/opt/anaconda3/envs/castle/lib/python3.13/site-packages/wandb/sdk/lib/sock_client.py", line 174, in send_record_publish
    self.send_server_request(server_req)
    ~~~~~~~~~~~~~~~~~~~~~~~~^^^^^^^^^^^^
  File "/opt/anaconda3/envs/castle/lib/python3.13/site-packages/wandb/sdk/lib/sock_client.py", line 154, in send_server_request
    self._send_message(msg)
    ~~~~~~~~~~~~~~~~~~^^^^^
  File "/opt/anaconda3/envs/castle/lib/python3.13/site-packages/wandb/sdk/lib/sock_client.py", line 151, in _send_message
    self._sendall_with_error_handle(header + data)
    ~~~~~~~~~~~~~~~~~~~~~~~~~~~~~~~^^^^^^^^^^^^^^^
  File "/opt/anaconda3/envs/castle/lib/python3.13/site-packages/wandb/sdk/lib/sock_client.py", line 130, in _sendall_with_error_handle
    sent = self._sock.send(data)
BrokenPipeError: [Errno 32] Broken pipe
